Workbook

Sheet Eval Dataset
A1: query_id | B1: language | C1: region | D1: city_country | E1: scenario | F1: user_query | G1: constraints | H1: must_have | I1: must_not_have
A2: 1 | B2: en | C2: Europe | D2: Prague, Czechia | E2: Простой поиск мест | F2: Find cozy coffee shops in Prague Old Town. | G2: category: coffee shops; area: Old Town; atmosphere: cozy | H2: 2–5 реальных мест нужной категории; правильный город/район; краткое объяснение релевантности; соблюдение указанных предпочтений. | I2: Несуществующие места; другая категория; места вне указанной локации; неподтвержденные конкретные факты.
A3: 2 | B3: en | C3: Europe | D3: Berlin, Germany | E3: Простой поиск мест | F3: Recommend contemporary art museums in Berlin. | G3: category: contemporary art museums | H3: 2–5 реальных мест нужной категории; правильный город/район; краткое объяснение релевантности; соблюдение указанных предпочтений. | I3: Несуществующие места; другая категория; места вне указанной локации; неподтвержденные конкретные факты.
A4: 3 | B4: en | C4: Europe | D4: Lisbon, Portugal | E4: Простой поиск мест | F4: Find the best viewpoints in Lisbon for sunset. | G4: category: viewpoints; time: sunset | H4: 2–5 реальных мест нужной категории; правильный город/район; краткое объяснение релевантности; соблюдение указанных предпочтений. | I4: Несуществующие места; другая категория; места вне указанной локации; неподтвержденные конкретные факты.
A5: 4 | B5: en | C5: Europe | D5: Rome, Italy | E5: Простой поиск мест | F5: Suggest traditional trattorias in Trastevere. | G5: category: traditional trattorias; area: Trastevere | H5: 2–5 реальных мест нужной категории; правильный город/район; краткое объяснение релевантности; соблюдение указанных предпочтений. | I5: Несуществующие места; другая категория; места вне указанной локации; неподтвержденные конкретные факты.
A6: 5 | B6: en | C6: Europe | D6: Amsterdam, Netherlands | E6: Простой поиск мест | F6: Find quiet parks in Amsterdam for a relaxed afternoon. | G6: category: parks; atmosphere: quiet; time: afternoon | H6: 2–5 реальных мест нужной категории; правильный город/район; краткое объяснение релевантности; соблюдение указанных предпочтений. | I6: Несуществующие места; другая категория; места вне указанной локации; неподтвержденные конкретные факты.
A7: 6 | B7: en | C7: Europe | D7: Athens, Greece | E7: Простой поиск мест | F7: Recommend archaeological sites in central Athens. | G7: category: archaeological sites; area: city centre | H7: 2–5 реальных мест нужной категории; правильный город/район; краткое объяснение релевантности; соблюдение указанных предпочтений. | I7: Несуществующие места; другая категория; места вне указанной локации; неподтвержденные конкретные факты.
A8: 7 | B8: en | C8: Europe | D8: Copenhagen, Denmark | E8: Простой поиск мест | F8: Find independent Danish design shops in Copenhagen. | G8: category: design shops; independent/local | H8: 2–5 реальных мест нужной категории; правильный город/район; краткое объяснение релевантности; соблюдение указанных предпочтений. | I8: Несуществующие места; другая категория; места вне указанной локации; неподтвержденные конкретные факты.
A9: 8 | B9: ru | C9: Europe | D9: London, United Kingdom | E9: Простой поиск мест | F9: Порекомендуй бесплатные музеи в центре Лондона. | G9: категория: музеи; цена: бесплатно; район: центр | H9: 2–5 реальных мест нужной категории; правильный город/район; краткое объяснение релевантности; соблюдение указанных предпочтений. | I9: Несуществующие места; другая категория; места вне указанной локации; неподтвержденные конкретные факты.
A10: 9 | B10: ru | C10: Europe | D10: Barcelona, Spain | E10: Простой поиск мест | F10: Найди хорошие веганские кафе в Барселоне. | G10: категория: веганские кафе | H10: 2–5 реальных мест нужной категории; правильный город/район; краткое объяснение релевантности; соблюдение указанных предпочтений. | I10: Несуществующие места; другая категория; места вне указанной локации; неподтвержденные конкретные факты.
A11: 10 | B11: en | C11: CIS | D11: Almaty, Kazakhstan | E11: Простой поиск мест | F11: Find family-friendly parks in Almaty. | G11: category: parks; family-friendly | H11: 2–5 реальных мест нужной категории; правильный город/район; краткое объяснение релевантности; соблюдение указанных предпочтений. | I11: Несуществующие места; другая категория; места вне указанной локации; неподтвержденные конкретные факты.
A12: 11 | B12: en | C12: CIS | D12: Tbilisi, Georgia | E12: Простой поиск мест | F12: Suggest local bakeries in central Tbilisi. | G12: category: local bakeries; area: centre | H12: 2–5 реальных мест нужной категории; правильный город/район; краткое объяснение релевантности; соблюдение указанных предпочтений. | I12: Несуществующие места; другая категория; места вне указанной локации; неподтвержденные конкретные факты.
A13: 12 | B13: en | C13: CIS | D13: Baku, Azerbaijan | E13: Простой поиск мест | F13: Find historical museums in Baku. | G13: category: historical museums | H13: 2–5 реальных мест нужной категории; правильный город/район; краткое объяснение релевантности; соблюдение указанных предпочтений. | I13: Несуществующие места; другая категория; места вне указанной локации; неподтвержденные конкретные факты.
... A101: 100 | B101: en | C101: CIS | D101: Almaty, Kazakhstan | E101: Неполные / неоднозначные запросы | F101: I will be in Almaty for a while. Make me a plan. | G101: missing: exact duration, dates, interests, budget | H101: 1–3 точных уточняющих вопроса либо базовый вариант с явно обозначенными предположениями; указание, каких данных не хватает. | I101: Чрезмерно конкретный уверенный план без оснований; скрытые предположения; игнорирование неоднозначности запроса.

Sheet Results
A1: query_id | B1: language | C1: region | D1: city_country | E1: scenario | F1: user_query | G1: model | H1: prompt_version | I1: tool_outputs | J1: model_answer | K1: intent | L1: relevance | M1: factuality | N1: feasibility | O1: format | P1: critical_error | Q1: error_type | R1: overall_score | S1: evaluator_notes | T1: run_date
A2: 1 | B2: en | C2: Europe | D2: Prague, Czechia | E2: Простой поиск мест | F2: Find cozy coffee shops in Prague Old Town. | H2: geoagent v1 ( qwen3-8b) | K2: 0.8 | L2: 0.8 | M2: 0.4 | O2: 1 | R2: =IF(A2="","",IF(OR(E2="Маршрут на один день",E2="Планирование поездки на несколько дней"),IF(COUNT(K2:O2)<5,"",MIN(K2*0.2+L2*0.2+M2*0.25+N2*0.25+O2*0.1,IF(P2="Да",2,5))),IF(COUNT(K2:M2)+COUNT(O2)<4,"",MIN(K2*0.25+L2*0.25+M2*0.35+O2*0.15,IF(P2="Да",2,5))))) -> 0.69
A3: 2 | B3: en | C3: Europe | D3: Berlin, Germany | E3: Простой поиск мест | F3: Recommend contemporary art museums in Berlin. | H3: geoagent v1 ( qwen3-8b) | K3: 5 | L3: 4 | M3: 1 | O3: 5 | R3: =IF(A3="","",IF(OR(E3="Маршрут на один день",E3="Планирование поездки на несколько дней"),IF(COUNT(K3:O3)<5,"",MIN(K3*0.2+L3*0.2+M3*0.25+N3*0.25+O3*0.1,IF(P3="Да",2,5))),IF(COUNT(K3:M3)+COUNT(O3)<4,"",MIN(K3*0.25+L3*0.25+M3*0.35+O3*0.15,IF(P3="Да",2,5))))) -> 3.35
A4: 3 | B4: en | C4: Europe | D4: Lisbon, Portugal | E4: Простой поиск мест | F4: Find the best viewpoints in Lisbon for sunset. | H4: geoagent v1 ( qwen3-8b) | K4: 5 | L4: 4 | M4: 2 | O4: 5 | R4: =IF(A4="","",IF(OR(E4="Маршрут на один день",E4="Планирование поездки на несколько дней"),IF(COUNT(K4:O4)<5,"",MIN(K4*0.2+L4*0.2+M4*0.25+N4*0.25+O4*0.1,IF(P4="Да",2,5))),IF(COUNT(K4:M4)+COUNT(O4)<4,"",MIN(K4*0.25+L4*0.25+M4*0.35+O4*0.15,IF(P4="Да",2,5))))) -> 3.7
A5: 4 | B5: en | C5: Europe | D5: Rome, Italy | E5: Простой поиск мест | F5: Suggest traditional trattorias in Trastevere. | H5: geoagent v1 ( qwen3-8b) | K5: 5 | L5: 5 | M5: 3 | O5: 5 | R5: =IF(A5="","",IF(OR(E5="Маршрут на один день",E5="Планирование поездки на несколько дней"),IF(COUNT(K5:O5)<5,"",MIN(K5*0.2+L5*0.2+M5*0.25+N5*0.25+O5*0.1,IF(P5="Да",2,5))),IF(COUNT(K5:M5)+COUNT(O5)<4,"",MIN(K5*0.25+L5*0.25+M5*0.35+O5*0.15,IF(P5="Да",2,5))))) -> 4.3
A6: 5 | B6: en | C6: Europe | D6: Amsterdam, Netherlands | E6: Простой поиск мест | F6: Find quiet parks in Amsterdam for a relaxed afternoon. | H6: geoagent v1 ( qwen3-8b) | K6: 4 | L6: 3 | M6: 1 | O6: 5 | R6: =IF(A6="","",IF(OR(E6="Маршрут на один день",E6="Планирование поездки на несколько дней"),IF(COUNT(K6:O6)<5,"",MIN(K6*0.2+L6*0.2+M6*0.25+N6*0.25+O6*0.1,IF(P6="Да",2,5))),IF(COUNT(K6:M6)+COUNT(O6)<4,"",MIN(K6*0.25+L6*0.25+M6*0.35+O6*0.15,IF(P6="Да",2,5))))) -> 2.85
A7: 6 | B7: en | C7: Europe | D7: Athens, Greece | E7: Простой поиск мест | F7: Recommend archaeological sites in central Athens. | H7: geoagent v1 ( qwen3-8b) | K7: 5 | L7: 5 | M7: 2 | O7: 5 | R7: =IF(A7="","",IF(OR(E7="Маршрут на один день",E7="Планирование поездки на несколько дней"),IF(COUNT(K7:O7)<5,"",MIN(K7*0.2+L7*0.2+M7*0.25+N7*0.25+O7*0.1,IF(P7="Да",2,5))),IF(COUNT(K7:M7)+COUNT(O7)<4,"",MIN(K7*0.25+L7*0.25+M7*0.35+O7*0.15,IF(P7="Да",2,5))))) -> 3.95
A8: 7 | B8: en | C8: Europe | D8: Copenhagen, Denmark | E8: Простой поиск мест | F8: Find independent Danish design shops in Copenhagen. | H8: geoagent v1 ( qwen3-8b) | K8: 4 | L8: 2 | M8: 1 | O8: 4 | R8: =IF(A8="","",IF(OR(E8="Маршрут на один день",E8="Планирование поездки на несколько дней"),IF(COUNT(K8:O8)<5,"",MIN(K8*0.2+L8*0.2+M8*0.25+N8*0.25+O8*0.1,IF(P8="Да",2,5))),IF(COUNT(K8:M8)+COUNT(O8)<4,"",MIN(K8*0.25+L8*0.25+M8*0.35+O8*0.15,IF(P8="Да",2,5))))) -> 2.45
A9: 8 | B9: ru | C9: Europe | D9: London, United Kingdom | E9: Простой поиск мест | F9: Порекомендуй бесплатные музеи в центре Лондона. | H9: geoagent v1 ( qwen3-8b) | K9: 5 | L9: 4 | M9: 2 | O9: 4 | R9: =IF(A9="","",IF(OR(E9="Маршрут на один день",E9="Планирование поездки на несколько дней"),IF(COUNT(K9:O9)<5,"",MIN(K9*0.2+L9*0.2+M9*0.25+N9*0.25+O9*0.1,IF(P9="Да",2,5))),IF(COUNT(K9:M9)+COUNT(O9)<4,"",MIN(K9*0.25+L9*0.25+M9*0.35+O9*0.15,IF(P9="Да",2,5))))) -> 3.55
A10: 9 | B10: ru | C10: Europe | D10: Barcelona, Spain | E10: Простой поиск мест | F10: Найди хорошие веганские кафе в Барселоне. | H10: geoagent v1 ( qwen3-8b) | K10: 5 | L10: 4 | M10: 2 | O10: 5 | R10: =IF(A10="","",IF(OR(E10="Маршрут на один день",E10="Планирование поездки на несколько дней"),IF(COUNT(K10:O10)<5,"",MIN(K10*0.2+L10*0.2+M10*0.25+N10*0.25+O10*0.1,IF(P10="Да",2,5))),IF(COUNT(K10:M10)+COUNT(O10)<4,"",MIN(K10*0.25+L10*0.25+M10*0.35+O10*0.15,IF(P10="Да",2,5))))) -> 3.7
A11: 10 | B11: en | C11: CIS | D11: Almaty, Kazakhstan | E11: Простой поиск мест | F11: Find family-friendly parks in Almaty. | H11: geoagent v1 ( qwen3-8b) | K11: 2 | L11: 2 | M11: 1 | O11: 5 | R11: =IF(A11="","",IF(OR(E11="Маршрут на один день",E11="Планирование поездки на несколько дней"),IF(COUNT(K11:O11)<5,"",MIN(K11*0.2+L11*0.2+M11*0.25+N11*0.25+O11*0.1,IF(P11="Да",2,5))),IF(COUNT(K11:M11)+COUNT(O11)<4,"",MIN(K11*0.25+L11*0.25+M11*0.35+O11*0.15,IF(P11="Да",2,5))))) -> 2.1
A12: 11 | B12: en | C12: CIS | D12: Tbilisi, Georgia | E12: Простой поиск мест | F12: Suggest local bakeries in central Tbilisi. | H12: geoagent v1 ( qwen3-8b) | K12: 3 | L12: 3 | M12: 1 | O12: 3 | R12: =IF(A12="","",IF(OR(E12="Маршрут на один день",E12="Планирование поездки на несколько дней"),IF(COUNT(K12:O12)<5,"",MIN(K12*0.2+L12*0.2+M12*0.25+N12*0.25+O12*0.1,IF(P12="Да",2,5))),IF(COUNT(K12:M12)+COUNT(O12)<4,"",MIN(K12*0.25+L12*0.25+M12*0.35+O12*0.15,IF(P12="Да",2,5))))) -> 2.3
A13: 12 | B13: en | C13: CIS | D13: Baku, Azerbaijan | E13: Простой поиск мест | F13: Find historical museums in Baku. | H13: geoagent v1 ( qwen3-8b) | K13: 3 | L13: 3 | M13: 1 | O13: 4 | R13: =IF(A13="","",IF(OR(E13="Маршрут на один день",E13="Планирование поездки на несколько дней"),IF(COUNT(K13:O13)<5,"",MIN(K13*0.2+L13*0.2+M13*0.25+N13*0.25+O13*0.1,IF(P13="Да",2,5))),IF(COUNT(K13:M13)+COUNT(O13)<4,"",MIN(K13*0.25+L13*0.25+M13*0.35+O13*0.15,IF(P13="Да",2,5))))) -> 2.45
... A31: 30 | B31: ru | C31: CIS | D31: Almaty, Kazakhstan | E31: Проверка информации о конкретном месте | F31: Сколько стоит вход в Государственный музей искусств имени Кастеева и во сколько он закрывается? | H31: geoagent v1 ( qwen3-8b) | K31: 5 | L31: 4 | M31: 2 | O31: 5 | R31: =IF(A31="","",IF(OR(E31="Маршрут на один день",E31="Планирование поездки на несколько дней"),IF(COUNT(K31:O31)<5,"",MIN(K31*0.2+L31*0.2+M31*0.25+N31*0.25+O31*0.1,IF(P31="Да",2,5))),IF(COUNT(K31:M31)+COUNT(O31)<4,"",MIN(K31*0.25+L31*0.25+M31*0.35+O31*0.15,IF(P31="Да",2,5))))) -> 3.7
A32: 31 | B32: en | C32: Europe | D32: Prague, Czechia | E32: Поиск мест рядом с заданной точкой | F32: Find good cafes within 800 metres of Charles Bridge. | H32: geoagent v1 ( qwen3-8b) | K32: 5 | L32: 5 | M32: 4 | O32: 5 | R32: =IF(A32="","",IF(OR(E32="Маршрут на один день",E32="Планирование поездки на несколько дней"),IF(COUNT(K32:O32)<5,"",MIN(K32*0.2+L32*0.2+M32*0.25+N32*0.25+O32*0.1,IF(P32="Да",2,5))),IF(COUNT(K32:M32)+COUNT(O32)<4,"",MIN(K32*0.25+L32*0.25+M32*0.35+O32*0.15,IF(P32="Да",2,5))))) -> 4.65 | S32: Не удалось завершить запрос в отведённое число шагов.
A33: 32 | B33: en | C33: Europe | D33: Paris, France | E33: Поиск мест рядом с заданной точкой | F33: Find affordable restaurants within a 10-minute walk of Gare du Nord. | H33: geoagent v1 ( qwen3-8b) | K33: 5 | L33: 4 | M33: 3 | O33: 5 | R33: =IF(A33="","",IF(OR(E33="Маршрут на один день",E33="Планирование поездки на несколько дней"),IF(COUNT(K33:O33)<5,"",MIN(K33*0.2+L33*0.2+M33*0.25+N33*0.25+O33*0.1,IF(P33="Да",2,5))),IF(COUNT(K33:M33)+COUNT(O33)<4,"",MIN(K33*0.25+L33*0.25+M33*0.35+O33*0.15,IF(P33="Да",2,5))))) -> 4.05 | S33: Не удалось завершить запрос в отведённое число шагов.
A34: 33 | B34: en | C34: Europe | D34: Rome, Italy | E34: Поиск мест рядом с заданной точкой | F34: Recommend gelato shops within 1 km of the Colosseum. | H34: geoagent v1 ( qwen3-8b) | K34: 2 | L34: 2 | M34: 1 | O34: 4 | R34: =IF(A34="","",IF(OR(E34="Маршрут на один день",E34="Планирование поездки на несколько дней"),IF(COUNT(K34:O34)<5,"",MIN(K34*0.2+L34*0.2+M34*0.25+N34*0.25+O34*0.1,IF(P34="Да",2,5))),IF(COUNT(K34:M34)+COUNT(O34)<4,"",MIN(K34*0.25+L34*0.25+M34*0.35+O34*0.15,IF(P34="Да",2,5))))) -> 1.95
A35: 34 | B35: en | C35: Europe | D35: Vienna, Austria | E35: Поиск мест рядом с заданной точкой | F35: Find museums within 2 km of Vienna Hauptbahnhof. | H35: geoagent v1 ( qwen3-8b) | K35: 2 | L35: 2 | M35: 1 | O35: 5 | R35: =IF(A35="","",IF(OR(E35="Маршрут на один день",E35="Планирование поездки на несколько дней"),IF(COUNT(K35:O35)<5,"",MIN(K35*0.2+L35*0.2+M35*0.25+N35*0.25+O35*0.1,IF(P35="Да",2,5))),IF(COUNT(K35:M35)+COUNT(O35)<4,"",MIN(K35*0.25+L35*0.25+M35*0.35+O35*0.15,IF(P35="Да",2,5))))) -> 2.1
A36: 35 | B36: en | C36: Europe | D36: Barcelona, Spain | E36: Поиск мест рядом с заданной точкой | F36: Find breakfast places within a 15-minute walk of Plaça de Catalunya. | H36: geoagent v1 ( qwen3-8b) | K36: 2 | L36: 1 | M36: 1 | O36: 5 | R36: =IF(A36="","",IF(OR(E36="Маршрут на один день",E36="Планирование поездки на несколько дней"),IF(COUNT(K36:O36)<5,"",MIN(K36*0.2+L36*0.2+M36*0.25+N36*0.25+O36*0.1,IF(P36="Да",2,5))),IF(COUNT(K36:M36)+COUNT(O36)<4,"",MIN(K36*0.25+L36*0.25+M36*0.35+O36*0.15,IF(P36="Да",2,5))))) -> 1.85
A37: 36 | B37: en | C37: Europe | D37: London, United Kingdom | E37: Поиск мест рядом с заданной точкой | F37: Suggest quiet parks near the British Museum. | H37: geoagent v1 ( qwen3-8b) | K37: 4 | L37: 4 | M37: 2 | O37: 5 | R37: =IF(A37="","",IF(OR(E37="Маршрут на один день",E37="Планирование поездки на несколько дней"),IF(COUNT(K37:O37)<5,"",MIN(K37*0.2+L37*0.2+M37*0.25+N37*0.25+O37*0.1,IF(P37="Да",2,5))),IF(COUNT(K37:M37)+COUNT(O37)<4,"",MIN(K37*0.25+L37*0.25+M37*0.35+O37*0.15,IF(P37="Да",2,5))))) -> 3.45
A38: 37 | B38: ru | C38: Europe | D38: Paris, France | E38: Поиск мест рядом с заданной точкой | F38: Найди уютные кафе в радиусе километра от Лувра. | H38: geoagent v1 ( qwen3-8b) | K38: 4 | L38: 4 | M38: 3 | O38: 4 | R38: =IF(A38="","",IF(OR(E38="Маршрут на один день",E38="Планирование поездки на несколько дней"),IF(COUNT(K38:O38)<5,"",MIN(K38*0.2+L38*0.2+M38*0.25+N38*0.25+O38*0.1,IF(P38="Да",2,5))),IF(COUNT(K38:M38)+COUNT(O38)<4,"",MIN(K38*0.25+L38*0.25+M38*0.35+O38*0.15,IF(P38="Да",2,5))))) -> 3.65
A39: 38 | B39: ru | C39: Europe | D39: Berlin, Germany | E39: Поиск мест рядом с заданной точкой | F39: Порекомендуй вегетарианские рестораны в пределах 15 минут пешком от Бранденбургских ворот. | H39: geoagent v1 ( qwen3-8b) | K39: 2 | L39: 2 | M39: 1 | O39: 5 | R39: =IF(A39="","",IF(OR(E39="Маршрут на один день",E39="Планирование поездки на несколько дней"),IF(COUNT(K39:O39)<5,"",MIN(K39*0.2+L39*0.2+M39*0.25+N39*0.25+O39*0.1,IF(P39="Да",2,5))),IF(COUNT(K39:M39)+COUNT(O39)<4,"",MIN(K39*0.25+L39*0.25+M39*0.35+O39*0.15,IF(P39="Да",2,5))))) -> 2.1
A40: 39 | B40: ru | C40: Europe | D40: Amsterdam, Netherlands | E40: Поиск мест рядом с заданной точкой | F40: Найди небольшие музеи рядом с площадью Дам. | H40: geoagent v1 ( qwen3-8b) | K40: 3 | L40: 3 | M40: 1 | O40: 5 | R40: =IF(A40="","",IF(OR(E40="Маршрут на один день",E40="Планирование поездки на несколько дней"),IF(COUNT(K40:O40)<5,"",MIN(K40*0.2+L40*0.2+M40*0.25+N40*0.25+O40*0.1,IF(P40="Да",2,5))),IF(COUNT(K40:M40)+COUNT(O40)<4,"",MIN(K40*0.25+L40*0.25+M40*0.35+O40*0.15,IF(P40="Да",2,5))))) -> 2.6
A41: 40 | B41: en | C41: CIS | D41: Tbilisi, Georgia | E41: Поиск мест рядом с заданной точкой | F41: Find cafes within a 10-minute walk of Freedom Square in Tbilisi. | H41: geoagent v1 ( qwen3-8b) | K41: 3 | L41: 2 | M41: 1 | O41: 5 | R41: =IF(A41="","",IF(OR(E41="Маршрут на один день",E41="Планирование поездки на несколько дней"),IF(COUNT(K41:O41)<5,"",MIN(K41*0.2+L41*0.2+M41*0.25+N41*0.25+O41*0.1,IF(P41="Да",2,5))),IF(COUNT(K41:M41)+COUNT(O41)<4,"",MIN(K41*0.25+L41*0.25+M41*0.35+O41*0.15,IF(P41="Да",2,5))))) -> 2.35
A42: 41 | B42: en | C42: CIS | D42: Yerevan, Armenia | E42: Поиск мест рядом с заданной точкой | F42: Recommend Armenian restaurants near Republic Square in Yerevan. | H42: geoagent v1 ( qwen3-8b) | K42: 3 | L42: 2 | M42: 1 | O42: 5 | R42: =IF(A42="","",IF(OR(E42="Маршрут на один день",E42="Планирование поездки на несколько дней"),IF(COUNT(K42:O42)<5,"",MIN(K42*0.2+L42*0.2+M42*0.25+N42*0.25+O42*0.1,IF(P42="Да",2,5))),IF(COUNT(K42:M42)+COUNT(O42)<4,"",MIN(K42*0.25+L42*0.25+M42*0.35+O42*0.15,IF(P42="Да",2,5))))) -> 2.35
A43: 42 | B43: en | C43: CIS | D43: Moscow, Russia | E43: Поиск мест рядом с заданной точкой | F43: Find parks within 2 km of Red Square. | H43: geoagent v1 ( qwen3-8b) | K43: 3 | L43: 3 | M43: 3 | O43: 5 | R43: =IF(A43="","",IF(OR(E43="Маршрут на один день",E43="Планирование поездки на несколько дней"),IF(COUNT(K43:O43)<5,"",MIN(K43*0.2+L43*0.2+M43*0.25+N43*0.25+O43*0.1,IF(P43="Да",2,5))),IF(COUNT(K43:M43)+COUNT(O43)<4,"",MIN(K43*0.25+L43*0.25+M43*0.35+O43*0.15,IF(P43="Да",2,5))))) -> 3.3
A44: 43 | B44: en | C44: CIS | D44: Almaty, Kazakhstan | E44: Поиск мест рядом с заданной точкой | F44: Find coworking-friendly cafes near Abai Square in Almaty. | H44: geoagent v1 ( qwen3-8b) | K44: 3 | L44: 3 | M44: 2 | O44: 5 | R44: =IF(A44="","",IF(OR(E44="Маршрут на один день",E44="Планирование поездки на несколько дней"),IF(COUNT(K44:O44)<5,"",MIN(K44*0.2+L44*0.2+M44*0.25+N44*0.25+O44*0.1,IF(P44="Да",2,5))),IF(COUNT(K44:M44)+COUNT(O44)<4,"",MIN(K44*0.25+L44*0.25+M44*0.35+O44*0.15,IF(P44="Да",2,5))))) -> 2.95
A45: 44 | B45: ru | C45: CIS | D45: Saint Petersburg, Russia | E45: Поиск мест рядом с заданной точкой | F45: Найди рестораны русской кухни рядом с Дворцовой площадью. | H45: geoagent v1 ( qwen3-8b) | K45: 5 | L45: 4 | M45: 3 | O45: 5 | R45: =IF(A45="","",IF(OR(E45="Маршрут на один день",E45="Планирование поездки на несколько дней"),IF(COUNT(K45:O45)<5,"",MIN(K45*0.2+L45*0.2+M45*0.25+N45*0.25+O45*0.1,IF(P45="Да",2,5))),IF(COUNT(K45:M45)+COUNT(O45)<4,"",MIN(K45*0.25+L45*0.25+M45*0.35+O45*0.15,IF(P45="Да",2,5))))) -> 4.05
... A50: 49 | B50: en | C50: Europe | D50: Berlin, Germany | E50: Список мест для поездки | F50: Make a list of alternative culture spots, flea markets and inexpensive eateries in Berlin. | H50: geoagent v1 ( qwen3-8b) | K50: 5 | L50: 4 | M50: 2 | O50: 4 | R50: =IF(A50="","",IF(OR(E50="Маршрут на один день",E50="Планирование поездки на несколько дней"),IF(COUNT(K50:O50)<5,"",MIN(K50*0.2+L50*0.2+M50*0.25+N50*0.25+O50*0.1,IF(P50="Да",2,5))),IF(COUNT(K50:M50)+COUNT(O50)<4,"",MIN(K50*0.25+L50*0.25+M50*0.35+O50*0.15,IF(P50="Да",2,5))))) -> 3.55
A51: 50 | B51: en | C51: Europe | D51: Rome, Italy | E51: Список мест для поездки | F51: Suggest less crowded historical places and local restaurants in Rome. | G51: qwen/qwen3-30b-a3b-instruct-2507 | H51: geoagent v1 ( qwen3-8b) | I51: web_search(ok) | model_calls=2 tool_calls=1 grounded=true | J51: Here are some less crowded historical sites and authentic local restaurants in Rome, perfect for a more tranquil and immersive experience: --- ### 🏛️ **Less Crowded Historical Places in Rome** 1. **Clivus Scauri (Caelian Hill)** - *Location:* Between the Palatine and Caelian Hills - *Why visit:* This ancient Roman street is one of the best-preserved in the city, winding through a quiet, green area with a serene atmosphere. It’s far removed from the tourist crowds near the Colosseum and offers a peaceful journey through millennia of history. - *Highlights:* - The Basilica of Saints John and Paul - Roman Houses of the Caelian Hill (an archaeological complex with frescoes and layered history) - Panoramic views of Rome from the hilltop - *Tip:* Visit early in the morning to enjoy the tranquility and avoid midday heat. 2. **Villa Torlonia Museums and Park** - *Location:* Trastevere area, near the Janiculum Hill - *Why visit:* A hidden gem with a mix of ancient ruins, 19th-century architecture, and lush gardens. The park is expansive and rarely crowded, offering a peaceful escape. - *Highlights:* - The ruins of a Roman villa beneath the park - The elegant Villa Torlonia, once a residence of Mussolini - The Museum of the Italian Republic and the Museum of the 20th Century - *Tip:* Combine a visit with a walk along the Janiculum Hill for a stunning sunset view. 3. **Ostia Antica (Ancient Rome’s Port City)** - *Location:* 30 minutes by train from Rome (Porta San Paolo station) - *Why visit:* Often called “Rome’s Pompeii,” this well-preserved ancient city offers a quieter alternative to the crowded ruins in the city center. - *Highlights:* - Ancient streets, houses, baths, and mosaics - A peaceful atmosphere with fewer tourists - A perfect setting for a relaxed afternoon walk - *Tip:* Visit in the morning to avoid the midday heat and crowds. --- ### 🍝 **Authentic Local Restaurants in Rome** 1. **Ristorante Monumento dal 1884 (Ostia Antica)** - *Location:* Piazza Umberto I, 8, Ostia Antica - *Why go:* A century-old family-run restaurant that’s a local institution. It’s located right in the heart of Ostia Antica, making it ideal for a post-ruins seafood lunch. - *Must-try dishes:* - Linguine in bianco with clams, mussels, squid, and shrimp - Shrimp in brandy-lime sauce - Tiramisu (dense and rich, with a generous dusting of cacao) - *Atmosphere:* Sunny enclosed terrace, rustic charm, and warm hospitality. 2. **Trattoria da Enzo al 29** (Trastevere) - *Location:* Via dei Vascellari, 29, Trastevere - *Why go:* A beloved local favorite, tucked away in a quiet alley. It’s known for its traditional Roman cuisine and authentic atmosphere. - *Must-try dishes:* - Cacio e pepe (a classic Roman pasta) - Saltimbocca alla Romana (veal with prosciutto and sage) - Carciofi alla Romana (Roman-style artichokes) - *Tip:* Arrive early or make a reservation—this place is popular with locals and fills up quickly. 3. **La Montecarlo** (Testaccio) - *Location:* Via di Monte Testaccio, 10 - *Why go:* A no-frills, family-run spot known for its hearty Roman dishes and affordable prices. It’s a favorite among locals and foodies. - *Must-try dishes:* - Trippa alla Romana (Roman-style tripe) - Abbacchio alla scottadito (grilled lamb) - Pecorino cheese with honey - *Atmosphere:* Simple, rustic, and full of character. --- ### 🗺️ **Travel Tips** - **Best time to visit:** Early morning (before 10:00 AM) or late afternoon (after 4:00 PM) to avoid peak tourist hours. - **Transport:** Use the metro (Line A) to reach Ostia Antica and Trastevere. For the Caelian Hill and Villa Torlonia, a short walk or taxi is ideal. - **Dress code:** Comfortable walking shoes are essential—Rome is best explored on foot. Enjoy your journey through the quieter, more authentic side of Rome! 🇮🇹✨ | K51: 5 | L51: 4 | M51: 2 | O51: 5 | P51: Да | Q51: Wrong location within city; Hallucinated place; Unsupported factual claim | R51: =IF(A51="","",IF(OR(E51="Маршрут на один день",E51="Планирование поездки на несколько дней"),IF(COUNT(K51:O51)<5,"",MIN(K51*0.2+L51*0.2+M51*0.25+N51*0.25+O51*0.1,IF(P51="Да",2,5))),IF(COUNT(K51:M51)+COUNT(O51)<4,"",MIN(K51*0.25+L51*0.25+M51*0.35+O51*0.15,IF(P51="Да",2,5))))) -> 2 | S51: Формат строго списочный, обе категории покрыты, ставка на «нетуристическое» выдержана. Реальны и точны: Clivus Scauri с Римскими домами Целия и базиликой Сан-Джованни-э-Паоло, Остия-Антика, Trattoria da Enzo al 29 (Via dei Vascellari 29, Трастевере), Ristorante Monumento dal 1884 на Пьяцца Умберто I. Критично: вилла Торлония отнесена к Трастевере рядом с Яникулом — фактически Виа Номентана, северо-восток города; её музеи названы «Музей Итальянской Республики» и «Музей XX века» — таких там нет (Казино Нобиле, Казина делле Чиветте, Казино дей Принчипи), а под парком не «руины римской виллы», а еврейские катакомбы. La Montecarlo указана в Тестаччо (Via di Monte Testaccio 10) — реальная La Montecarlo это пиццерия у Пьяцца Навона. Совет ехать линией метро A в Остию-Антику и Трастевере неверен: Остия — линия Roma-Lido от Порта-Сан-Паоло. Подборка тонкая: по три позиции в каждой категории, две из шести привязаны к Остии. | T51: 46231
A52: 51 | B52: en | C52: Europe | D52: Vienna, Austria | E52: Список мест для поездки | F52: List places in Vienna for classical music, coffee culture and parks. | G52: qwen/qwen3-30b-a3b-instruct-2507 | H52: geoagent v1 ( qwen3-8b) | I52: web_search(ok); web_search(ok); web_search(ok) | model_calls=4 tool_calls=3 grounded=true | J52: Here is a curated list of the best places in Vienna for classical music, coffee culture, and parks, based on your interests: --- ### 🎻 **Classical Music Venues in Vienna** Vienna is renowned as the "City of Music," and its historic concert halls and churches offer world-class performances. 1. **The Musikverein** - One of the most prestigious concert halls in the world, home to the Vienna Philharmonic Orchestra. - Famous for the annual New Year’s Concert. - *Tip:* Book tickets in advance for performances of Mozart, Beethoven, and Strauss. 2. **Konzerthaus Wien** - A major venue for classical concerts, including symphonies, chamber music, and recitals. - Hosts the traditional **Christmas in Vienna** concert during the holiday season. 3. **Schönbrunn Palace Orangery** - A stunning setting for classical music concerts in a historic imperial garden. - Offers performances of works by Mozart, Haydn, and Vivaldi. 4. **Café Museum (Karlsplatz)** - A legendary coffee house with a long history of hosting live piano music (Fridays–Sundays, 4–7:30 PM). - Once frequented by Gustav Klimt and Adolf Loos. 5. **Konzert-Café Weimar (near Volksoper)** - Historic café with live piano music featuring operetta, jazz, and swing (Fri–Sun, 4–8 PM). --- ### ☕ **Iconic Coffee Houses for Viennese Coffee Culture** Vienna’s coffee house tradition is a UNESCO-recognized cultural heritage. These are the most authentic and beloved spots. 1. **Café Sacher Wien** - Famous for the **Original Sacher-Torte** and the **Sacher Coffee**. - Elegant, historic setting in the heart of Vienna. - A must-visit for a luxurious coffee and cake experience. 2. **Café Central** - A grand 19th-century café where Freud, Trotsky, and other intellectuals once gathered. - Known for its opulent interior and traditional Viennese pastries. 3. **Café Hawelka** - A legendary cultural hub with a bohemian atmosphere. - Famous for its **Buchteln** (jam-filled dough balls). - A favorite among artists and writers. 4. **Café Sperl** - One of the oldest coffee houses in Vienna (since 1880), with timeless decor. - Offers a genuine taste of old Vienna, including billiards and traditional cakes. 5. **Café Schwarzenberg** - A cozy, intimate spot with a literary vibe. - Known for its excellent coffee and relaxed ambiance. --- ### 🌳 **Top Parks in Vienna for Relaxation & Scenic Views** Vienna’s green spaces combine natural beauty with historical charm. 1. **Schloss Schönbrunn (Schönbrunn Palace Gardens)** - The imperial summer residence with magnificent baroque gardens. - Features fountains, a hedge maze, and the Gloriette (a triumphal arch with panoramic city views). - Ideal for a peaceful stroll or a picnic. 2. **Stadtpark (City Park)** - A serene green oasis near the Wien River, perfect for walking and cycling. - Home to a famous statue of Johann Strauss II. - Offers a tranquil escape from the city center. 3. **Prater Park** - Vienna’s largest public park, once a royal hunting ground. - Famous for the **Wiener Riesenrad (Vienna Ferris Wheel)**. - Great for picnics, cycling, and summer festivals. 4. **Lainzer Tiergarten** - A wild, forested park with free-roaming deer, boar, and birds. - A peaceful retreat for nature lovers and cross-country skiers in winter. 5. **Belvedere Palace Gardens** - Symmetrical French-style gardens between two grand palaces. - Features fountains, topiary, and stunning views of the palace and city skyline. --- ### ✅ **Recommended Experience Itinerary** - **Morning:** Start at **Café Sacher** for a traditional Viennese breakfast and a slice of Sacher-Torte. - **Afternoon:** Walk through **Stadtpark**, then visit **Café Central** for coffee and people-watching. - **Evening:** Attend a classical concert at **The Musikverein** or **Schönbrunn Orangery**. - **Optional:** End the day with a sunset stroll in **Schönbrunn Gardens**. Vienna beautifully blends music, coffee, and nature—perfect for a culturally rich and relaxing visit. | K52: 5 | L52: 4 | M52: 4 | O52: 5 | P52: Нет | Q52: Low relevance; Unsupported factual claim | R52: =IF(A52="","",IF(OR(E52="Маршрут на один день",E52="Планирование поездки на несколько дней"),IF(COUNT(K52:O52)<5,"",MIN(K52*0.2+L52*0.2+M52*0.25+N52*0.25+O52*0.1,IF(P52="Да",2,5))),IF(COUNT(K52:M52)+COUNT(O52)<4,"",MIN(K52*0.25+L52*0.25+M52*0.35+O52*0.15,IF(P52="Да",2,5))))) -> 4.4 | S52: Все три интереса покрыты реальными местами, формат списка. Кафе (Café Museum, Konzert-Café Weimar) отнесены в раздел классической музыки. Указаны конкретные часы живой музыки — не подтверждаются. В конце добавлен мини-маршрут, но список остаётся основным. | T52: 46231
A53: 52 | B53: en | C53: Europe | D53: Copenhagen, Denmark | E53: Список мест для поездки | F53: Suggest places in Copenhagen for design, modern architecture and food markets. | G53: qwen/qwen3-30b-a3b-instruct-2507 | H53: geoagent v1 ( qwen3-8b) | I53: web_search(ok) | model_calls=2 tool_calls=1 grounded=true | J53: Here are some top recommendations in Copenhagen for design, modern architecture, and food markets: --- ### 🏛️ **1. BLOX – Urban Life, Architecture & Sustainability** - **Why visit**: A striking example of modern architecture designed by renowned Dutch architects OMA. Located on Copenhagen’s central harbor front, BLOX is a hub for urban innovation, design, and sustainability. - **Highlights**: - **Danish Architecture Center (DAC)**: Hosts exhibitions on Danish and international architecture, design, and urban development. - **Design Shop**: Curated selection of Danish jewelry, watches, fashion, books, and design objects. - **BLOX EATS**: A vibrant café and restaurant with outdoor seating, perfect for a modern dining experience. - **Rental Apartments**: 22 stylish apartments with rooftop terraces (ideal for extended stays). - **Location**: Harbor front, Copenhagen. - **Website**: [www.blox.dk](https://www.blox.dk) --- ### 🍴 **2. Reffen – The Largest Street Food Market in the Nordics** - **Why visit**: A dynamic, waterfront food market that blends global street food with sustainable design and cultural events. - **Highlights**: - Over 50 food stalls offering cuisines from around the world (e.g., Thai, Mexican, Middle Eastern, and Nordic). - Unique architecture using repurposed shipping containers and reclaimed materials. - Regular live music, art installations, and seasonal events. - Open daily, making it a great spot for both lunch and evening outings. - **Location**: Former industrial harbor area, close to the city center. - **Website**: [reffen.dk](https://www.reffen.dk) --- ### 🏙️ **3. The Danish Architecture Center (DAC) – Inside BLOX** - **Why visit**: A must-visit for design and architecture enthusiasts. The center showcases the evolution of Danish design and urban planning. - **Highlights**: - **"So Danish!" Exhibition**: A sensory journey through 1,000 years of Danish architecture and design, featuring models, films, drawings, and installations. - **Events & Workshops**: Regular talks, lectures, and interactive sessions on architecture and sustainability. - **Café & Shop**: Relax with a coffee and browse unique design products. - **Location**: Inside BLOX, Copenhagen. - **Website**: [dac.dk](https://dac.dk) --- ### 🌿 **4. Superkilen Park – A Design-Driven Urban Space** - **Why visit**: A bold, colorful public park designed by the Danish firm BIG (Bjarke Ingels Group) in collaboration with Topotek 1 and Superflex. - **Highlights**: - A fusion of global cultures represented through architecture, art, and landscape design. - Features iconic elements like a red square, a black street, and a green park — each symbolizing a different cultural region. - A great place for a walk, photography, or simply experiencing innovative urban design. - **Location**: Nørrebro district, central Copenhagen. - **Website**: [superkilen.dk](https://www.superkilen.dk) --- ### 🍽️ **5. Torvehallerne (The Old Market Hall) – Modern Food Market with Design Flair** - **Why visit**: A beautifully restored 19th-century market hall now transformed into a modern food destination with a strong design focus. - **Highlights**: - Over 30 vendors offering artisanal food, organic produce, gourmet treats, and craft beverages. - Elegant interior with exposed brick, glass, and modern lighting — a blend of old and new. - Hosts pop-up events, cooking classes, and food festivals. - **Location**: Vesterbro, near the city center. - **Website**: [torvehallerne.dk](https://www.torvehallerne.dk) --- ### ✅ **Summary:** | Category | Recommended Place | |--------|-------------------| | **Modern Architecture** | BLOX, Superkilen Park | | **Design & Culture** | Danish Architecture Center (DAC), BLOX Design Shop | | **Food Markets** | Reffen, Torvehallerne | These locations offer a perfect blend of cutting-edge design, architectural innovation, and culinary experiences — all in the heart of Copenhagen. Let me know if you’d like a walking route or a day itinerary combining these spots! | K53: 5 | L53: 4 | M53: 4 | O53: 5 | P53: Нет | Q53: Unsupported factual claim; Too verbose | R53: =IF(A53="","",IF(OR(E53="Маршрут на один день",E53="Планирование поездки на несколько дней"),IF(COUNT(K53:O53)<5,"",MIN(K53*0.2+L53*0.2+M53*0.25+N53*0.25+O53*0.1,IF(P53="Да",2,5))),IF(COUNT(K53:M53)+COUNT(O53)<4,"",MIN(K53*0.25+L53*0.25+M53*0.35+O53*0.15,IF(P53="Да",2,5))))) -> 4.4 | S53: BLOX, Reffen, Superkilen, Torvehallerne, DAC — реальные, авторы (OMA, BIG) указаны верно. Torvehallerne отнесён к Vesterbro, фактически Indre By / Israels Plads. DAC и BLOX разнесены в два пункта, хотя это одно здание — дублирование сокращает реальную подборку. | T53: 46231
A54: 53 | B54: ru | C54: Europe | D54: Budapest, Hungary | E54: Список мест для поездки | F54: Составь список мест в Будапеште для терм, архитектуры и венгерской кухни. | G54: qwen/qwen3-30b-a3b-instruct-2507 | H54: geoagent v1 ( qwen3-8b) | I54: web_search(ok) | model_calls=2 tool_calls=1 grounded=true | J54: Вот подборка мест в Будапеште, которые идеально сочетают термальные источники, архитектурные достопримечательности и аутентичную венгерскую кухню: --- ### 🛁 **Термальные источники (термы)** 1. **Купальня Сечени (Széchenyi Gyógyfürdő)** - **Особенности**: Самая большая термальная баня в Европе, расположена на берегу Дуная. Включает 18 бассейнов, в том числе открытые, с термальной водой (36–40 °C). - **Атмосфера**: Оживлённая, популярна среди туристов и местных жителей. - **Совет**: Посетите вечером, чтобы насладиться видом на подсвеченный Парламент. - **Ссылка**: [Сечени — официальный сайт](https://www.szechenyygyogyfurdo.hu) 2. **Купальня Рудаш (Rudas Baths)** - **Особенности**: Историческая баня с османским наследием, построенная в XVI веке. Центральный восьмиугольный бассейн под рёбристым куполом с витражами — настоящий архитектурный шедевр. - **Атмосфера**: Тихая, созерцательная, идеальна для релаксации. - **Совет**: Посетите утром — свет, проникающий через витражи, особенно красив. - **Ссылка**: [Rudas Baths — официальный сайт](https://www.rudasbaths.hu) 3. **Купальня Геллерт (Gellért Baths)** - **Особенности**: Современный велнес-комплекс с историческим ядром. Включает бассейны, сауны, соляные пещеры и крытый бассейн с видом на Дунай. - **Важно**: В настоящее время закрыта на реконструкцию до 2028 года. - **Альтернатива**: Посетите **Купальню Лукач (Lukács Baths)** — более спокойная, с архитектурой в стиле модерн. --- ### 🏛️ **Архитектурные достопримечательности** 1. **Парламент Венгрии (Hungarian Parliament Building)** - **Особенности**: Неоготический шедевр на берегу Дуная. Внутри — великолепные залы, мозаики, башни. - **Совет**: Пройдитесь по балкону на верхнем этаже — панорама на Пешт и Дунай потрясающая. - **Экскурсии**: Доступны на нескольких языках. 2. **Замковый район и Рыбацкий бастион (Buda Castle & Fisherman’s Bastion)** - **Особенности**: Исторический холм с панорамными видами. - **Достопримечательности**: - Будайский замок (с музеями) - Церковь Святого Матяша - Лабиринт подземелий - **Совет**: Посетите вечером — виды на Пешт в свете особенно впечатляют. 3. **Проспект Андраши (Andrássy Avenue)** - **Особенности**: Пешеходный бульвар в стиле парижских проспектов. - **Достопримечательности**: - Площадь Героев (Hősök tere) - Театр оперы и балета - Архитектурные фасады в стиле неоклассицизма и модерна --- ### 🍽️ **Венгерская кухня** 1. **VakVarjú (на крыше Будайского замка)** - **Особенности**: Ресторан с панорамным видом на Пешт и Дунай. - **Кухня**: Современная венгерская с элементами фьюжн. - **Совет**: Закажите "гуляш с булочками" и венгерское вино. 2. **Bazár Várkert (у подножия Королевского дворца)** - **Особенности**: Рыночный комплекс с уличной едой и ресторанами. - **Рекомендации**: - "Гуляш" в традиционной керамической миске - "Палотас" — венгерский бутерброд с сыром и ветчиной - "Добош" — сладкий пирог с творогом 3. **Mézes Kör (Мёдовый круг)** - **Особенности**: Уютный ресторан в центре Пешта, известный своими традиционными блюдами. - **Рекомендации**: - "Суп из бобов с колбасой" - "Халаш" — венгерский хлеб с сыром - "Добош" с ванильным кремом --- ### 🗺️ **Совет по маршруту дня** 1. Утро: **Купальня Рудаш** (утренний свет в витражах) 2. День: **Замковый район + Рыбацкий бастион** (панорама + экскурсия) 3. Обед: **Bazár Várkерт** (вкусная уличная еда) 4. Вечер: **Парламент + круиз по Дунаю** (подсвеченный город) 5. Ужин: **VakVarjú** (панорама + венгерская кухня) --- Если хотите, могу составить **подробный маршрут на 1–3 дня** с учётом времени, транспорта и бронирования. | K54: 5 | L54: 4 | M54: 2 | O54: 4 | P54: Да | Q54: Hallucinated place; Unsupported factual claim; Wrong location within city | R54: =IF(A54="","",IF(OR(E54="Маршрут на один день",E54="Планирование поездки на несколько дней"),IF(COUNT(K54:O54)<5,"",MIN(K54*0.2+L54*0.2+M54*0.25+N54*0.25+O54*0.1,IF(P54="Да",2,5))),IF(COUNT(K54:M54)+COUNT(O54)<4,"",MIN(K54*0.25+L54*0.25+M54*0.35+O54*0.15,IF(P54="Да",2,5))))) -> 2 | S54: Термы и архитектура — реальные. Критично: ресторан «Mézes Kör» не идентифицируется; Сечени указана «на берегу Дуная» (фактически Варошлигет); ссылка szechenyygyogyfurdo.hu нерабочая; Várkert Bazár описан как рынок уличной еды; описания блюд неверны («Добош — пирог с творогом», «Халаш — хлеб с сыром», «Палотас»). Смешение кириллицы и латиницы в тексте. | T54: 46231
A55: 54 | B55: ru | C55: Europe | D55: Athens, Greece | E55: Список мест для поездки | F55: Порекомендуй места в Афинах для античной истории, видов на город и местной еды. | G55: qwen/qwen3-30b-a3b-instruct-2507 | H55: geoagent v1 ( qwen3-8b) | I55: web_search(ok) | model_calls=2 tool_calls=1 grounded=true | J55: Вот рекомендации по местам в Афинах, которые идеально сочетают античную историю, панорамные виды на город и возможность попробовать местную греческую кухню: --- ### 🏛️ **1. Акрополь Афин** - **Что посмотреть**: Главный символ древнегреческой цивилизации — храм Парфенон, Эрехтейон с портиком кариатид, храм Ники и Пропилеи. - **Виды**: Панорамный 360° вид на весь город с вершины холма. Особенно красив на закате. - **Местная еда**: Ресторан на вершине холма (часовня Святого Георгия) предлагает традиционные греческие блюда с видом на Акрополь. - **Совет**: Купите комбинированный билет (30 € на 5 дней) для посещения Акрополя и других музеев. - **Адрес**: Афинский Акрополь, Афины, Греция - **Ссылка**: [src_658dc90bf5](https://journest.app/athens-acropolis) --- ### 🏞️ **2. Холм Ликавитос** - **Что посмотреть**: Самая высокая точка Афин (277 м), с которой открывается великолепный вид на город, Акрополь и Средиземное море. - **Виды**: Панорама на 360° — идеально для фото и закатов. - **Местная еда**: На вершине — ресторан с традиционной греческой кухней (ламбаджия, мусака, тзазики). - **Доступ**: Подъём на фуникулёре или пешком по тропе. - **Адрес**: Улица Аристиппу, Колонаки, Афины - **Ссылка**: [src_f7567e59f4](https://journest.app/likavitos) --- ### 🏺 **3. Древняя Агора** - **Что посмотреть**: Сердце древнегреческой Афин — рынок, политический центр и место встреч. Здесь сохранился **Храм Гефеста** — один из лучших примеров древнегреческой архитектуры. - **Виды**: Вид на Акрополь с южной стороны. - **Местная еда**: Рядом — **Центральный рынок Варвакейос Агора**, где можно попробовать свежие продукты, сыр, оливки, фета и традиционные закуски. - **Совет**: Посетите **Стоа Аттала** — музей Агоры, где собраны археологические находки. - **Адрес**: Adrianou 24, Афины 105 55 - **Ссылка**: [src_78eb6bb418](https://journest.app/ancient-athens-agora) --- ### 🏺 **4. Национальный археологический музей** - **Что посмотреть**: Один из крупнейших археологических музеев мира. Здесь хранятся **золотая маска Агамемнона**, **Антикитерский механизм** и другие уникальные экспонаты. - **Виды**: Прекрасный вид на город с террасы музея. - **Местная еда**: Рядом — рестораны в районе Плака, где подают блюда в стиле «гриль» и традиционные греческие закуски. - **Адрес**: 28–30, Пирейская улица, Афины - **Ссылка**: [src_3f27b266f8](https://journest.app/national-archaeological-museum) --- ### 🍽️ **5. Район Плака (Plaka)** - **Что посмотреть**: Старый город, улочки с винтажными домами, лавки с сувенирами и ресторанами. - **Виды**: Виды на Акрополь с улиц и террас. - **Местная еда**: Множество ресторанов с традиционной греческой кухней: **Oinomageia**, **To Koutouki**, **Kostas** — здесь подают мусаку, салаты, кебабы и домашние десерты. - **Совет**: Посетите вечером — атмосфера особенно волшебная. - **Адрес**: Район Плака, Афины - **Ссылка**: [src_78eb6bb418](https://journest.app/ancient-athens-agora) --- ### ✅ **Итоговая рекомендация по маршруту**: 1. Утро: **Акрополь** (с посещением музея и храма Парфенон). 2. Обед: **Храм Гефеста** + прогулка по **Древней Агоре** + ужин в **Варвакейос Агора**. 3. Вечер: Подъём на **Ликавитос** на закат, ужин в ресторане на вершине. 4. Ночь: Прогулка по **Плаке** и дегустация местной еды. --- Если хотите, могу помочь составить **подробный маршрут на день** или **рекомендации по отелям** в этих районах. | K55: 5 | L55: 4 | M55: 2 | O55: 3 | P55: Да | Q55: Unsupported factual claim; Wrong location within city; Poor formatting | R55: =IF(A55="","",IF(OR(E55="Маршрут на один день",E55="Планирование поездки на несколько дней"),IF(COUNT(K55:O55)<5,"",MIN(K55*0.2+L55*0.2+M55*0.25+N55*0.25+O55*0.1,IF(P55="Да",2,5))),IF(COUNT(K55:M55)+COUNT(O55)<4,"",MIN(K55*0.25+L55*0.25+M55*0.35+O55*0.15,IF(P55="Да",2,5))))) -> 2 | S55: Акрополь, Агора, Ликавитос, Плака — реальные и покрывают запрос. Критично: часовня Св. Георгия и ресторан на вершине отнесены к Акрополю (это Ликавитос); адрес Национального археологического музея неверен (фактически ул. Патисион 44); блюдо «ламбаджия» выдумано. В текст утекли сырые id источников (src_...), ссылки journest.app нерабочие. | T55: 46231
A56: 55 | B56: en | C56: CIS | D56: Tbilisi, Georgia | E56: Список мест для поездки | F56: I am going to Tbilisi for four days. Suggest places for culture, Georgian food and panoramic views. | G56: qwen/qwen3-30b-a3b-instruct-2507 | H56: geoagent v1 ( qwen3-8b) | I56: web_search(ok); web_search(ok); web_search(ok) | model_calls=2 tool_calls=3 grounded=true | J56: Here’s a curated 4-day travel plan for your trip to **Tbilisi**, focusing on **culture**, **authentic Georgian cuisine**, and **panoramic views**. The recommendations are based on up-to-date information from trusted sources. --- ### 🌆 **Day 1: Explore Old Town & Cultural Heart** **Focus:** History, architecture, and iconic landmarks. - **Morning: Old Town Tbilisi** Start your journey in the historic **Old Town**, a maze of cobbled streets, 19th-century townhouses, and hidden courtyards. Wander through **Sololaki** and **Shardeni Street**, known for its charming alleys and vibrant café culture. - **Midday: Sioni Cathedral** Visit the **Sioni Cathedral** (6th century), the spiritual heart of Tbilisi. Admire its ancient architecture and view the **Cross of St. Nino**, Georgia’s holiest relic. - **Afternoon: Rustaveli Avenue & National Museum** Stroll down **Rustaveli Avenue**, Tbilisi’s grand boulevard. Stop by the **National Museum of Georgia** and the **Opera House**. The avenue is perfect for people-watching and soaking in the city’s energy. - **Evening: Sunset at Narikala Fortress** Head to **Narikala Fortress** (4th century) for panoramic views. Take the **cable car from Rike Park** (₾5) or hike up from **Abanotubani** (20 min). Best time: **one hour before sunset** for golden-hour photos. --- ### 🍽️ **Day 2: Georgian Food & Culinary Immersion** **Focus:** Authentic cuisine, traditional dining, and cultural experiences. - **Lunch: Ethno Tsiskvili (A. Beliashvili St. 99)** Dine at **Ethno Tsiskvili**, a cultural restaurant with a natural waterfall and traditional Georgian decor. Enjoy **khachapuri**, **khinkali**, and **barbecue**. Don’t miss the **live folk music and dance performances** (20:00–00:00). - **Afternoon: Vakhtanguri Restaurant (Old Town)** Visit **Vakhtanguri**, a beloved local institution since 1993. Try their famous **chebureki** (spiced meat turnovers) and other family-recipe dishes. The atmosphere is warm and nostalgic. - **Evening: Wine Tasting in the Old Town** Explore **wine bars** along **Shardeni Street** or **Tbilisi’s underground wine cellars** (like **Nikoloz’s Cellar**). Sample **Saperavi**, **Rkatsiteli**, and other local varietals. --- ### 🌄 **Day 3: Panoramic Views & Mountain Vibes** **Focus:** Elevated city views, parks, and relaxation. - **Morning: Mtatsminda Park & Funicular** Take the **funicular** from **Rustaveli Avenue** to **Mtatsminda Park**. Enjoy the ride and the **observation deck** with sweeping views of Tbilisi, the Kura River, and the Greater Caucasus Range. - **Midday: Ferris Wheel & Cafés** Ride the **Ferris wheel** for a 360° view. Grab a coffee at one of the park’s cafés and enjoy the mountain breeze. - **Afternoon: Bridge of Peace & Kura River Walk** Walk across the **Bridge of Peace**, a modern architectural gem. Stroll along the **Kura River** and enjoy views of the city skyline. - **Evening: Dinner at Tsiskvili Terrace (Z. Gamsakhurdia Embankment)** Dine with a view at **Tsiskvili Terrace**, a riverside restaurant offering panoramic city views and excellent Georgian cuisine. --- ### 🏛️ **Day 4: Museums, Monuments & Final Impressions** **Focus:** Culture, history, and memorable souvenirs. - **Morning: Chronicles of Georgia & Art Palace** Visit **Chronicles of Georgia**, a museum dedicated to Georgia’s history and national identity. Then explore the **Art Palace of Georgia – Museum of Cultural History** for insights into Georgian art and traditions. - **Midday: Rezo Gabriadze Marionette Theater** Watch a performance at the **Rezo Gabriadze Marionette Theater**, a unique cultural gem in the Old Town. The puppet shows are both artistic and deeply rooted in Georgian folklore. - **Afternoon: Final Walk & Souvenirs** Take a final walk through **Old Town**, pick up souvenirs like **Georgian wine**, **pomegranate molasses**, or **handmade ceramics** from local shops. - **Evening: Farewell Dinner at Wine Yard (A. Beliashvili St. 99)** End your trip with a relaxed dinner at **Wine Yard**, another gem in the Tsiskvili Group, known for its cozy atmosphere and excellent wine pairings. --- ### 📌 **Tips for Your Trip:** - **Best Time to Visit:** Spring (April–June) or early autumn (September–October) for pleasant weather. - **Transport:** Use the **funicular**, **cable car**, or **walk**—Tbilisi is very walkable. - **Currency:** Georgian Lari (GEL). ATMs are widely available. - **Travel Insurance:** Mandatory since 2026 (as per recent regulations). --- Enjoy your unforgettable journey through **Tbilisi**—a city where ancient history, vibrant culture, and breathtaking views come together in perfect harmony. 🇬🇪✨ | K56: 3 | L56: 3 | M56: 2 | O56: 4 | P56: Да | Q56: Low relevance; Unsupported factual claim; Hallucinated place | R56: =IF(A56="","",IF(OR(E56="Маршрут на один день",E56="Планирование поездки на несколько дней"),IF(COUNT(K56:O56)<5,"",MIN(K56*0.2+L56*0.2+M56*0.25+N56*0.25+O56*0.1,IF(P56="Да",2,5))),IF(COUNT(K56:M56)+COUNT(O56)<4,"",MIN(K56*0.25+L56*0.25+M56*0.35+O56*0.15,IF(P56="Да",2,5))))) -> 2 | S56: Пользователь просил список, агент выдал жёсткий маршрут по дням. Критично: утверждение «Travel Insurance: Mandatory since 2026» выдумано; цена канатной дороги ₾5 не соответствует действительности; заведения Vakhtanguri, Nikoloz's Cellar, Tsiskvili Terrace не подтверждаются. Нарикала, Сиони, Мтацминда, Мост Мира, Хроники Грузии — реальные. | T56: 46231
A57: 56 | B57: en | C57: CIS | D57: Yerevan, Armenia | E57: Список мест для поездки | F57: List places in Yerevan for history, Armenian cuisine and contemporary art. | G57: qwen/qwen3-30b-a3b-instruct-2507 | H57: geoagent v1 ( qwen3-8b) | I57: web_search(ok); web_search(ok); web_search(ok) | model_calls=4 tool_calls=3 grounded=true | J57: Here is a curated list of places in Yerevan that offer a rich experience in **history**, **Armenian cuisine**, and **contemporary art**, based on the latest available information: --- ### 🏺 **Historical Sites in Yerevan** 1. **Erebuni Fortress & Museum-Reserve** - **Location**: Southeastern suburbs of Yerevan - **Significance**: Founded in 782 BC by King Argishti I of Urartu, Erebuni is the oldest known foundation of Yerevan. The name "Yerevan" itself derives from "Erebuni." - **Highlights**: Ancient ruins, archaeological museum, panoramic views of the city. - **Visit Tip**: Combine with a visit to the adjacent **Erebuni Museum of History** (separate entry fee). - **Website**: [Erebuni Museum](https://en.wikipedia.org/wiki/Erebuni_Fortress) - **Address**: Erebuni District, Yerevan, Armenia 2. **Katoghike Church (Holy Mother of God Church)** - **Location**: Kentron District, central Yerevan - **Significance**: A 13th-century medieval church discovered during the demolition of a 17th-century basilica in 1936. It’s one of the oldest surviving churches in the city. - **Highlights**: Historical preservation, ancient khachkars (cross-stones), and architectural resilience. - **Address**: Kentron District, Yerevan, Armenia --- ### 🍽️ **Best Places for Armenian Cuisine** 1. **The Club** - **Location**: Tumanyan 40, Yerevan - **Cuisine**: Modern Armenian (New Armenian Cuisine) - **Highlights**: - Zero-waste restaurant using locally sourced ingredients. - Seasonal menu with innovative dishes inspired by Armenian highland traditions. - Wine cellar featuring wines from the Vayots Dzor region. - Hosts cultural events: concerts, lectures, book presentations. - **Ambience**: Intimate, artistic, and sustainable. - **Hours**: Daily 13:00–23:30 - **Contact**: +374 10 531361 | [Website](https://theclub.am) --- ### 🎨 **Contemporary Art Spaces in Yerevan** 1. **Cafesjian Center for the Arts (CCA)** - **Location**: The Cascade Complex, Yerevan - **Highlights**: - Dedicated to modern and contemporary art from Armenia and globally. - Features exhibitions from the **Cafesjian Art Trust**, including works by renowned artists. - Offers lectures, film screenings, concerts, and educational programs. - **Architecture**: Housed in the iconic **Cascade**, a monumental stairway complex designed by architect Alexander Tamanyan. - **Address**: Cascade Complex, Yerevan, Armenia - **Website**: [www.cmf.am](https://www.cmf.am) 2. **Esquisse Gallery** - **Location**: Sayat-Nova 5, Yerevan - **Focus**: International contemporary art and emerging Armenian artists. - **Highlights**: - Promotes cross-cultural dialogue through exhibitions. - Showcases artists with global recognition. - **Contact**: +374 95 555109 - **Website**: [esquissegallery.com](https://esquissegallery.com) 3. **Gala Art Gallery** - **Location**: Yerevan (exact address not specified, but active in the city center) - **Focus**: Modern and contemporary paintings, sculpture, and pottery by over 40 Armenian artists. - **Founded**: 2012 by Avetis Berberyan and Noushik Mikayelian. - **Website**: [gala-artgallery.am](https://gala-artgallery.am) 4. **Two Arcs Art Space** - **Location**: 5 Sayat-Nova Avenue, Yerevan - **Highlights**: A dynamic space for contemporary art exhibitions and artist residencies. - **Contact**: +374 43 490 490 | [Website](https://www.twoarcs.am) 5. **ARAR Gallery** - **Location**: Abovyan 13, Yerevan - **Focus**: Experimental and socially engaged contemporary art. - **Notable Projects**: Collaborations with the IPBA Foundation to bring art to public spaces. - **Website**: [arargallery.com](https://arargallery.com) --- ### ✅ **Suggested Itinerary for a Cultural Day in Yerevan** 1. **Morning**: Visit **Erebuni Fortress** and **Erebuni Museum** (history). 2. **Lunch**: Enjoy authentic Armenian cuisine at **The Club** (culinary experience). 3. **Afternoon**: Explore **Cafesjian Center for the Arts** (contemporary art). 4. **Evening**: Stroll through **The Cascade**, then visit **Esquisse Gallery** or **ARAR Gallery** for a night of art and culture. --- Let me know if you’d like help booking tickets, planning a multi-day trip, or finding accommodations near these sites! | K57: 5 | L57: 4 | M57: 4 | O57: 4 | P57: Нет | Q57: Missing important category; Unsupported factual claim | R57: =IF(A57="","",IF(OR(E57="Маршрут на один день",E57="Планирование поездки на несколько дней"),IF(COUNT(K57:O57)<5,"",MIN(K57*0.2+L57*0.2+M57*0.25+N57*0.25+O57*0.1,IF(P57="Да",2,5))),IF(COUNT(K57:M57)+COUNT(O57)<4,"",MIN(K57*0.25+L57*0.25+M57*0.35+O57*0.15,IF(P57="Да",2,5))))) -> 4.25 | S57: Все места реальные, история и современное искусство раскрыты хорошо (Эребуни, Катогике, Кафесчян, Esquisse, Two Arcs, ARAR). Кухня представлена одним заведением при пяти арт-площадках - категория недораскрыта. Часы работы и телефоны даны без подтверждения. Каскад приписан Таманяну - упрощение. | T57: 46231
