Workbook

Sheet Eval Dataset
A1: query_id | B1: language | C1: region | D1: city_country | E1: scenario | F1: request
A2: 1 | B2: en | C2: Europe | D2: Prague, Czechia | E2: Простой поиск мест | F2: Find cozy coffee shops in Prague Old Town.
A3: 2 | B3: en | C3: Europe | D3: Berlin, Germany | E3: Простой поиск мест | F3: Recommend contemporary art museums in Berlin.
A4: 3 | B4: en | C4: Europe | D4: Lisbon, Portugal | E4: Простой поиск мест | F4: Find the best viewpoints in Lisbon for sunset.
A5: 4 | B5: en | C5: Europe | D5: Rome, Italy | E5: Простой поиск мест | F5: Suggest traditional trattorias in Trastevere.
A6: 5 | B6: en | C6: Europe | D6: Amsterdam, Netherlands | E6: Простой поиск мест | F6: Find quiet parks in Amsterdam for a relaxed afternoon.
A7: 6 | B7: en | C7: Europe | D7: Athens, Greece | E7: Простой поиск мест | F7: Recommend archaeological sites in central Athens.
A8: 7 | B8: en | C8: Europe | D8: Copenhagen, Denmark | E8: Простой поиск мест | F8: Find independent Danish design shops in Copenhagen.
A9: 8 | B9: ru | C9: Europe | D9: London, United Kingdom | E9: Простой поиск мест | F9: Порекомендуй бесплатные музеи в центре Лондона.
A10: 9 | B10: ru | C10: Europe | D10: Barcelona, Spain | E10: Простой поиск мест | F10: Найди хорошие веганские кафе в Барселоне.
A11: 10 | B11: en | C11: CIS | D11: Almaty, Kazakhstan | E11: Простой поиск мест | F11: Find family-friendly parks in Almaty.
A12: 11 | B12: en | C12: CIS | D12: Tbilisi, Georgia | E12: Простой поиск мест | F12: Suggest local bakeries in central Tbilisi.
A13: 12 | B13: en | C13: CIS | D13: Baku, Azerbaijan | E13: Простой поиск мест | F13: Find historical museums in Baku.
... A161: 160 | B161: en | C161: Europe | D161: Berlin, Germany | E161: Неполные / неоднозначные запросы | F161: Is it better to spend your time in Berlin in a cultural way, exploring various attractions, or in a chaotic manner without a specific plan?

Sheet Results
A1: query_id | B1: request | C1: answer | D1: answer_with_tools | E1: gate_passed | F1: gate reason | G1: intent | H1: usefulness | I1: factuality | J1: format | K1: constraint adherence | L1: novelty | M1: completeness | N1: overall
A2: 1 | B2: Find cozy coffee shops in Prague Old Town. | C2: Вот несколько уютных кофеен в районе Старого города Праги: ### ☕ Týnská 9 **Адрес:** Týnská 626/9, Praha 1 (всего ~100 метров от Староместской площади) Описание: Тихое кафе в самом сердце Старого города — настоящая оазис тишины. Уютное пространство с арочными сводами, разноцветными скатертями и волшебным двориком с колодцем и плющом. Вечером вас встретят светящиеся гирлянды, а днём — красочные цветы. Идеальное место для чтения, работы за ноутбуком или спокойной беседы. **Часы работы:** ежедневно с 10:00 до 22:00 --- ### ☕ Café Revoluční **Адрес:** Soukenická / Revoluční 1084/14, Nové Město (110 00 Praha) Описание: Кофейня с выбором кофе, домашней выпечкой и бранчем. Интерьер выполнен в тёплых тонах с использованием дерева, мягких цветов и приятного освещения — здесь действительно хочется остаться подольше. Не является сетью и не ориентирована на туристов. **Часы работы:** сегодня, 10 августа, с 07:30 до 18:30 **Телефон:** +420 725 722 887 --- ### ☕ Coffe cube, stánek s nápoji **Адрес:** náměstí Republiky 656/8c stánek **Часы работы:** пн–сб 08:00–19:00 **Статус:** открыто сейчас --- ### ☕ Coffe café, kavárna **Адрес:** Štěpánská 626/63 **Часы работы:** пн–сб 08:00–20:00 **Статус:** открыто сейчас --- *Информация о часах работы актуальна на 10 августа 2026 года.* | D2: Tool result (places_search): {"places":[{"ref":"plc_b244d44328","id":"70000001007533319","name":"Coffe cube, stánek s nápoji","address":"Praha, náměstí Republiky 656/8c stánek","categories":["Fresh bary / Stánky s nealko koktejly / horkými nápoji"],"phones":[],"rating":null,"review_count":null,"hours_text":"пн–сб 08:00–19:00","open_24h":null,"is_open_now":true,"accessibility":[],"distance_m":363},{"ref":"plc_031e84751d","id":"70000001024458517","name":"Coffe café, kavárna","address":"Praha, Štěpánská 626/63","categories":["Kavárny"],"phones":[],"rating":null,"review_count":null,"hours_text":"пн–сб 08:00–20:00","open_24h":null,"is_open_now":true,"accessibility":[],"distance_m":900}],"area":null,"truncated":false,"anchor":"plc_c28e29a276","resolved":[],"returned_count":2} Tool result (web_search): {"query":"cozy coffee shops Prague Old Town","results":[{"ref":"src_979c90a20b","title":"Týnská 9 | Silent café in Prague Old Town","domain":"tynska9.com","snippet":"Týnská 9 | Silent café in Prague Old Town --\n...\nTýnská 9\n...\nCafé & Bar\n...\n## In the Heart of\n...\nYou can find us just 100 meters far from the Old Town Square, the very centre of Prague.\n...\nWe are the right place where you can have Prague's local beer, near-made ciders or fine Moravian wine.\n...\n## Are you looking for a quiet place, where you can contemplate with a book, have a game of chess with a friend, do some work on your laptop, or just have a nice chat? Týnská 9 is exactly that.\n...\nOn a little back street, almost on the Old Town Square, is a magical place, an oasis of silence. A yard with a well and ivy climbing up the walls. In the yard, there is a cosy little café. It has an arched ceiling and the tables are covered with colourful tablecloths. If you come here after dark, you will be greeted by floating fairy lights. If you arrive in daylight, you will see a colourful scenery made up of flowers. This is where our family and friends work. We work here because we like meeting and talking to people, and we like to offer them something nice to drink and to eat. If you come over, you might bump into someone sharing photographs from their journey, or witness one of the art shows that regularly take place there. We kindly invite you to come and enjoy the atmosphere of this unique space.\n...\nOpen daily from 10 am to 10 pm\n...\nThe choice of Dacaffé was a result of years and years of hanging around various cafés in Prague and pretending to understand the coffee.\n...\n, it seems that we learned something - our guests love Dacaffé, Prague's supplier of coffee:\n...\n- www.tynska9.cz\n- info[at]tynska9.cz\n- +420 727 937 998\n- Týnská 9, Praha 1, 110 00, Czech Republic","published_date":null},{"_omitted_items":8},{"ref":"src_cd225fd3cb","title":"Café Revolučni | Výběrová kavárna Praha 1 – Domácí dezerty, pekárna & brunch","domain":"caferevolucni.cz","snippet":"Café Revolučni | Výběrov\n...\nPraha 1 – Domácí dezerty\n...\nAre you looking for a café in Prague 1 where you can have a truly great coffee, a homemade dessert, or a brunch you'll still be thinking about next week? Then you've come to the right place.Café Revoluční stands on the corner of Revoluční Street in Nové Město. We are not a chain. We are not a tourist trap. We are a café, bistro, and homemade bakery all in one. A place where every day, from morning, things are baked, cooked, and prepared with care. This page will show you exactly what you'll find here and why guests are happy to keep coming back.Café Revoluční was created as a place that emphasizes three things: quality of ingredients, design of the space, and a human approach. No semi-finished products, no industrial bread, no coffee from inferior beans.\n...\nThe address Revoluční 1084/14 is not just a number. It is a place in the heart of Prague's historic center, a few minutes' walk from náměstí Republiky (Republic Square), Josefov, and the riverfront. The interior was designed by two architects: Petra Šmejkalová and Andrea Šetinová, and the result speaks for itself. Warm wood, soft colors, pleasant lighting, seating that truly invites you to stay. Coming here in the morning with a laptop, meeting a friend for brunch, or having an afternoon dessert with coffee — every scenario works here.\n...\nBrunch in Prague\n...\n— why ours is differentWe serve brunch every day, all\n...\n, in the heart of Prague 1\n...\nfind the same full menu\n...\n3 in the afternoon\n...\neven if you'\n...\nhad a late\n...\nof this — and none of it gets in\n...\na birthday brunch\n...\na café in the heart\n...\na distribution warehouse\n...\nRevoluční 1084/14 110 00, Nové Město\n...\nAdressRevoluční 1084/14110 00, Nové MěstoContact 725 722 887 info@","published_date":null}]} Tool result (places_search): {"places":[],"area":null,"truncated":false,"anchor":null,"resolved":[{"client_id":"candidate_1","input_name":"Týnská 9","status":"resolved","place":{"ref":"plc_30924460b3","id":"12948484583879079","name":"Týnská 626/9","address":"Praha, Týnská 626/9","categories":[],"phones":[],"rating":null,"review_count":null,"hours_text":null,"open_24h":null,"is_open_now":null,"accessibility":[],"distance_m":null},"options":[],"error":null},{"client_id":"candidate_2","input_name":"Café Revoluční","status":"resolved","place":{"ref":"plc_612c61115b","id":"AZu43AFUay0ke1FsDdUqfQ","name":"Café Revoluční","address":"Soukenická, 110 00 Praha","categories":["restaurant","czech"],"phones":["+420 725 722 887"],"rating":null,"review_count":null,"hours_text":"Next 7 days: Aug 10–14 07:30–18:30; Aug 15 08:00–18:30; Aug 16 08:00–18:00","open_24h":false,"is_open_now":true,"accessibility":[],"distance_m":null},"options":[],"error":null},{"client_id":"candidate_3","input_name":"Coffe cube, stánek s nápoji","status":"resolved","place":{"ref":"plc_b244d44328","id":"70000001007533319","name":"Coffe cube, stánek s nápoji","address":"Praha, náměstí Republiky 656/8c stánek","categories":["Fresh bary / Stánky s nealko koktejly / horkými nápoji"],"phones":[],"rating":null,"review_count":null,"hours_text":"пн–сб 08:00–19:00","open_24h":null,"is_open_now":true,"accessibility":[],"distance_m":null},"options":[],"error":null},{"client_id":"candidate_4","input_name":"Coffe café, kavárna","status":"resolved","place":{"ref":"plc_031e84751d","id":"70000001024458517","name":"Coffe café, kavárna","address":"Praha, Štěpánská 626/63","categories":["Kavárny"],"phones":[],"rating":null,"review_count":null,"hours_text":"пн–сб 08:00–20:00","open_24h":null,"is_open_now":true,"accessibility":[],"distance_m":null},"options":[],"error":null}],"returned_count":4,"warnings":["2GIS place search returned no matches; retrying with TomTom."]} Final answer: Вот несколько уютных кофеен в районе Старого города Праги: ### ☕ Týnská 9 **Адрес:** Týnská 626/9, Praha 1 (всего ~100 метров от Староместской площади) Описание: Тихое кафе в самом сердце Старого города — настоящая оазис тишины. Уютное пространство с арочными сводами, разноцветными скатертями и волшебным двориком с колодцем и плющом. Вечером вас встретят светящиеся гирлянды, а днём — красочные цветы. Идеальное место для чтения, работы за ноутбуком или спокойной беседы. **Часы работы:** ежедневно с 10:00 до 22:00 --- ### ☕ Café Revoluční **Адрес:** Soukenická / Revoluční 1084/14, Nové Město (110 00 Praha) Описание: Кофейня с выбором кофе, домашней выпечкой и бранчем. Интерьер выполнен в тёплых тонах с использованием дерева, мягких цветов и приятного освещения — здесь действительно хочется остаться подольше. Не является сетью и не ориентирована на туристов. **Часы работы:** сегодня, 10 августа, с 07:30 до 18:30 **Телефон:** +420 725 722 887 --- ### ☕ Coffe cube, stánek s nápoji **Адрес:** náměstí Republiky 656/8c stánek **Часы работы:** пн–сб 08:00–19:00 **Статус:** открыто сейчас --- ### ☕ Coffe café, kavárna **Адрес:** Štěpánská 626/63 **Часы работы:** пн–сб 08:00–20:00 **Статус:** открыто сейчас --- *Информация о часах работы актуальна на 10 августа 2026 года.* | E2: FAIL | F2: Language missmatch | G2: 0 | H2: 0 | I2: 0 | K2: 0 | L2: 0 | M2: 0 | N2: =IF($E2="","",IF($E2="FAIL","FAIL",ROUND(G2*15%+H2*15%+I2*25%+J2*10%+K2*20%+M2*5%+L2*10%,2))) -> FAIL
A3: 2 | B3: Recommend contemporary art museums in Berlin. | C3: Вот основные музеи современного искусства в Берлине: ### 1. KW Institute for Contemporary Art - **Адрес:** Auguststraße 69, 10117 Berlin - **Телефон:** +49 30 2434590 - **Часы работы:** Сегодня (10 августа) 11:00–19:00; 11 августа закрыто; 12 августа 11:00–19:00; 13 августа 11:00–21:00; 14–16 августа 11:00–19:00 - **Открыто сейчас:** ✅ Да - **Описание:** Транснациональный институт, глубоко укоренённый в местном контексте. Не имеет постоянной коллекции, что обеспечивает гибкость и открытость. Специализируется на актуальных выставках и программах, отвечающих на вопросы современности. ### 2. Hamburger Bahnhof – Nationalgalerie der Gegenwart - **Адрес:** Invalidenstraße 50, 10557 Berlin - **Телефон:** +49 30 266424242 - **Часы работы:** Сегодня (10 августа) закрыто; 11–12 августа 10:00–18:00; 13 августа 10:00–20:00; 14–16 августа 10:00–18:00 - **Открыто сейчас:** ❌ Нет - **Описание:** Главный музей современного искусства Берлина. Расположен в здании бывшей железнодорожной станции XIX века. Представляет коллекции, специальные выставки и событийные форматы. Входной билет: 16,00 € (льготный 8,00 €), дети до 18 лет бесплатно. ### 3. Berlinische Galerie - **Адрес:** Alte Jakobstraße 124, 10969 Berlin - **Телефон:** +49 30 78902600 - **Часы работы:** Сегодня (10 августа) 10:00–18:00; 11 августа закрыто; 12 августа 10:00–18:00; 13 августа 10:00–20:00; 14–16 августа 10:00–18:00 - **Открыто сейчас:** ✅ Да - **Описание:** Музей современного искусства Берлина с серьёзным международным охватом программ. ### 4. Neue Nationalgalerie - **Адрес:** Potsdamer Straße 50, 10785 Berlin - **Телефон:** +49 30 266424242 - **Часы работы:** Сегодня (10 августа) закрыто; 11–12 августа 10:00–18:00; 13 августа 10:00–20:00; 14–16 августа 10:00–18:00 - **Открыто сейчас:** ❌ Нет - **Описание:** Часть Национальной галереи, специализирующаяся на искусстве XX–XXI веков. ### 5. Gropius Bau - **Адрес:** Niederkirchnerstraße 7, 10963 Berlin - **Телефон:** +49 30 254860 - **Описание:** Выставочная площадка с международным охватом программ современного искусства. ### 6. Sammlung Boros - **Адрес:** Reinhardtstraße 20, 10117 Berlin - **Телефон:** +49 30 27594065 - **Часы работы:** Сегодня (10 августа) закрыто; 13–16 августа 10:00–20:00 - **Описание:** Частная коллекция современного искусства, расположенная в бывшем бункере времён Второй мировой войны. --- **Примечание:** Сегодня (10 августа) открыты KW Institute for Contemporary Art и Berlinische Galerie. Остальные музеи откроются завтра (11 августа). *Источники:,* | D3: Tool result (places_search): {"places":[{"ref":"plc_130d1074d6","id":"62FqLZ8XAB0g5PifIo8huA","name":"Bode-Museum","address":"Am Kupfergraben 1, 10117 Berlin","categories":["museum"],"phones":["+49 30 266424242"],"rating":null,"review_count":null,"hours_text":"Next 7 days: Aug 10 closed; Aug 11–16 10:00–18:00","open_24h":false,"is_open_now":false,"accessibility":[],"distance_m":null},{"ref":"plc_9ba49d8728","id":"B4qfD2jyfhPan3KGAgbUuw","name":"New National Gallery","address":"Reichpietschufer 46, 10785 Berlin","categories":["museum"],"phones":["+49 30 2662651"],"rating":null,"review_count":null,"hours_text":null,"open_24h":null,"is_open_now":null,"accessibility":[],"distance_m":null},{"ref":"plc_86d205e6aa","id":"N097s3JWBtbnHGybIVMLgA","name":"Museum of Technology","address":"Tempelhofer Ufer 31, 10963 Berlin","categories":["museum"],"phones":["+49 30 4397340"],"rating":null,"review_count":null,"hours_text":null,"open_24h":null,"is_open_now":null,"accessibility":[],"distance_m":null},{"ref":"plc_289475b302","id":"K75k5d46RUzo1gxUMouREQ","name":"Sammlung Boros","address":"Reinhardtstraße 20, 10117 Berlin","categories":["museum"],"phones":["+49 30 27594065"],"rating":null,"review_count":null,"hours_text":"Next 7 days: Aug 10–12 closed; Aug 13–16 10:00–20:00","open_24h":false,"is_open_now":false,"accessibility":[],"distance_m":null},{"ref":"plc_f2f1c2539f","id":"N36mrtM_3kl4_SialxosTA","name":"Pergamon Museum","address":"Bodestraße 1, 10178 Berlin","categories":["museum"],"phones":["+49 30 266424242"],"rating":null,"review_count":null,"hours_text":"Next 7 days: Aug 10 closed; Aug 11–12 10:00–18:00; Aug 13 10:00–20:00; Aug 14–16 10:00–18:00","open_24h":false,"is_open_now":false,"accessibility":[],"distance_m":null},{"ref":"plc_fc63da8d00","id":"psdgFQ03O6jc1PgPKIx2Kg","name":"Altes Museum","address":"Am Lustgarten, 10178 Berlin","categories":["museum"],"phones":["+49 30 266424242"],"rating":null,"review_count":null,"hours_text":"Next 7 days: Aug 10 closed; Aug 11–16 10:00–18:00","open_24h":false,"is_open_now":false,"accessibility":[],"distance_m":null},{"ref":"plc_8fae6ed365","id":"QkGpHypwq0M7O02MGMMlVQ","name":"Neues Museum","address":"Bodestraße, 10178 Berlin","categories":["museum"],"phones":["+49 30 266424242"],"rating":null,"review_count":null,"hours_text":"Next 7 days: Aug 10 closed; Aug 11–16 10:00–18:00","open_24h":false,"is_open_now":false,"accessibility":[],"distance_m":null},{"ref":"plc_ddffa824dd","id":"Oz2lhDov2tODfrR82vN_ew","name":"Topography of Terror","address":"Niederkirchnerstraße 8, 10963 Berlin","categories":["museum"],"phones":["+49 30 25486703"],"rating":null,"review_count":null,"hours_text":"Next 7 days: Aug 10–16 10:00–20:00","open_24h":false,"is_open_now":true,"accessibility":[],"distance_m":null},{"ref":"plc_8bf1611d5b","id":"f8sdALrHhP-5Vljtu8sr7Q","name":"Classic Remise Berlin","address":"Wiebestraße 37, 10553 Berlin","categories":["museum"],"phones":["+49 30 3640780"],"rating":null,"review_count":null,"hours_text":"Next 7 days: Aug 10–15 08:00–20:00; Aug 16 10:00–20:00","open_24h":false,"is_open_now":true,"accessibility":[],"distance_m":null},{"ref":"plc_7d21835e86","id":"C9n4hK9bi6FHZCjjv_nc7A","name":"Deutsches Historisches Museum","address":"Unter den Linden 2, 10117 Berlin","categories":["museum"],"phones":["+49 30 203040"],"rating":null,"review_count":null,"hours_text":"Next 7 days: Aug 10–12 10:00–18:00; Aug 13 10:00–20:00; Aug 14–16 10:00–18:00","open_24h":false,"is_open_now":true,"accessibility":[],"distance_m":null}],"area":{"ref":"plc_5655f612cc","name":"Berlin","address":"Berlin, Deutschland"},"truncated":true,"anchor":null,"resolved":[],"returned_count":10,"warnings":["2GIS does not cover the requested locality; using TomTom."]} Tool result (web_search): {"query":"contemporary art museums in Berlin","results":[{"ref":"src_e4315ac44c","title":"KW Institute for Contemporary Art","domain":"www.kw-berlin.de","snippet":"KW Institute for Contemporary Art\n...\nKW Institute for Contemporary Art engages with the central questions of our time through the production, presentation, and discussion of art. Attuned to the evolving needs of Berlin’s artists and practitioners, KW occupies a unique position as a transnational institution deeply rooted in our local context. Without a permanent collection, flexibility and openness lie at the heart of what makes KW special, as well as creating dynamic and timely programming that resonates with our times and audience. Who we are\n...\nSupport KW and Berlin Biennale\n...\nKW Friends is a non-profit organisation in support of KW Institute for Contemporary Art and the Berlin Biennale for Contemporary Art. Become a Friend and discover our art-community!","published_date":null},{"_omitted_items":8},{"ref":"src_7809a395bb","title":"Museumsportal Berlin - Museum – Hamburger Bahnhof – Nationalgalerie der Gegenwart","domain":"www.museumsportal-berlin.de","snippet":"Museumsportal Berlin - Museum – Hamburger Bahnhof – Nationalgalerie der Gegenwart\n...\nenstraße\n...\nMuseum für Gegenwart\n...\nBerlin, Invaliden\n...\n50,\n...\nThe Hamburger Bahnhof - Nationalgalerie der Gegenwart is Berlin's museum for contemporary art, which presents collections, special exhibitions and event formats. It is the largest building of the Nationalgalerie, whose extensive holdings can also be found in the Alte Nationalgalerie, the Neue Nationalgalerie, the Museum Berggruen and the Scharf-Gerstenberg Collection. \n\nAs one of Berlin's major railway terminus stations of the 19th century, it has always been a place of arrival, departure and transition. This history still characterises the museum in the centre of Berlin today. Today, art and society meet here. Art as an expression of human experience opens up new perspectives on our present and invites debate. Art creates spaces for dialogue and encounters - everyone brings something of their own, and together a polyphonic space is created.\n...\n### Location,\n\n Invalidenstraße 50-51, 10557 Berlin \n\nThird-party OpenStreetMap cookies By loading the map, you accept OpenStreetMaps' privacy policy of OpenStreetMap.\n...\nEmail,\n...\n### Prices,\n\n Admission price 16,00 € \n\nHamburger Bahnhof Nationalgalerie der Gegenwart + temporary exhibitions\n\n Reduced price 8,00 € \n\nChildren and young people up to the age of 18 are admitted free of charge.\n...\nNationalgalerie\n...\nNationalgalerie\n...\nNationalgalerie\n...\nNationalgalerie\n...\nHamburger Bahnhof – National\n...\nHamburger Bahnhof – National\n...\nHamburger Bahnhof – National\n...\nHamburger Bahnhof – Nationalgalerie\n...\nHamburger Bahnhof – Nationalgalerie\n...\nHamburger Bahnhof – National\n...\nHamburger Bahnhof – Nationalgalerie der Gegenwart\n...\nHamburger Bahnhof – Nationalgalerie","published_date":null}]} Tool result (web_search): {"query":"best contemporary art museums Berlin list","results":[{"ref":"src_8477b7eaf5","title":"Art museums | visitBerlin.de","domain":"www.visitberlin.de","snippet":"The old masters, important Modernist works and contemporary art: In Berlin's art museums you can wander through all eras of art history.\n...\nPay a visit to Nefertiti in the Neues Museum(New Museum) a…","published_date":null},{"_omitted_items":8},{"ref":"src_15cd75a207","title":"Berlin Contemporary Art Map – Galleries & Artist-Run Spaces | 1 Cubic Meter","domain":"1cubicmeter.com","snippet":"On the institutional side, Berlin carries real weight. Hamburger Bahnhof, KW Institute for Contemporary Art, the Berlinische Galerie, and Gropius Bau all run programs with serious international reach…","published_date":null}]} Tool result (places_search): {"places":[],"area":null,"truncated":false,"anchor":null,"resolved":[{"client_id":"kw_institute","input_name":"KW Institute for Contemporary Art","status":"resolved","place":{"ref":"plc_b7ca608b38","id":"g-qiS25EQD4MPWRMaai6_w","name":"KW Institute for Contemporary Art","address":"Auguststraße 69, 10117 Berlin","categories":["museum"],"phones":["+49 30 2434590"],"rating":null,"review_count":null,"hours_text":"Next 7 days: Aug 10 11:00–19:00; Aug 11 closed; Aug 12 11:00–19:00; Aug 13 11:00–21:00; Aug 14–16 11:00–19:00","open_24h":false,"is_open_now":true,"accessibility":[],"distance_m":null},"options":[],"error":null},{"client_id":"hamburger_bahnhof","input_name":"Hamburger Bahnhof – Nationalgalerie der Gegenwart","status":"resolved","place":{"ref":"plc_70818d6680","id":"nEK1GUAVbZ3Qkbuq7Xf3Aw","name":"Hamburger Bahnhof-Nationalgalerie der Gegenwart","address":"Invalidenstraße 50, 10557 Berlin","categories":["museum"],"phones":["+49 30 266424242"],"rating":null,"review_count":null,"hours_text":"Next 7 days: Aug 10 closed; Aug 11–12 10:00–18:00; Aug 13 10:00–20:00; Aug 14 10:00–18:00; Aug 15–16 11:00–18:00","open_24h":false,"is_open_now":false,"accessibility":[],"distance_m":null},"options":[],"error":null},{"client_id":"berlinische_galerie","input_name":"Berlinische Galerie","status":"resolved","place":{"ref":"plc_7b0c73b08b","id":"Wc5e36L9ytb8zTCQGG5LVg","name":"Berlinische Galerie","address":"Alte Jakobstraße 124, 10969 Berlin","categories":["museum"],"phones":["+49 30 78902600"],"rating":null,"review_count":null,"hours_text":"Next 7 days: Aug 10 10:00–18:00; Aug 11 closed; Aug 12 10:00–18:00; Aug 13 10:00–20:00; Aug 14–16 10:00–18:00","open_24h":false,"is_open_now":true,"accessibility":[],"distance_m":null},"options":[],"error":null},{"client_id":"gropius_bau","input_name":"Gropius Bau","status":"resolved","place":{"ref":"plc_e9bc9536ef","id":"43CtefL5_ArV9s2FvBgsjQ","name":"Gropius-Bau","address":"Niederkirchnerstraße 7, 10963 Berlin","categories":["restaurant"],"phones":["+49 30 254860"],"rating":null,"review_count":null,"hours_text":null,"open_24h":null,"is_open_now":null,"accessibility":[],"distance_m":null},"options":[],"error":null},{"client_id":"neue_nationalgalerie","input_name":"Neue Nationalgalerie","status":"resolved","place":{"ref":"plc_0089f2f30f","id":"7bHZidh3Mef8hhSMoro3JA","name":"Neue Nationalgalerie","address":"Potsdamer Straße 50, 10785 Berlin","categories":["museum"],"phones":["+49 30 266424242"],"rating":null,"review_count":null,"hours_text":"Next 7 days: Aug 10 closed; Aug 11–12 10:00–18:00; Aug 13 10:00–20:00; Aug 14–16 10:00–18:00","open_24h":false,"is_open_now":false,"accessibility":[],"distance_m":null},"options":[],"error":null}],"returned_count":5,"warnings":["2GIS does not cover the requested locality; using TomTom."]} Final answer: Вот основные музеи современного искусства в Берлине: ### 1. KW Institute for Contemporary Art - **Адрес:** Auguststraße 69, 10117 Berlin - **Телефон:** +49 30 2434590 - **Часы работы:** Сегодня (10 августа) 11:00–19:00; 11 августа закрыто; 12 августа 11:00–19:00; 13 августа 11:00–21:00; 14–16 августа 11:00–19:00 - **Открыто сейчас:** ✅ Да - **Описание:** Транснациональный институт, глубоко укоренённый в местном контексте. Не имеет постоянной коллекции, что обеспечивает гибкость и открытость. Специализируется на актуальных выставках и программах, отвечающих на вопросы современности. ### 2. Hamburger Bahnhof – Nationalgalerie der Gegenwart - **Адрес:** Invalidenstraße 50, 10557 Berlin - **Телефон:** +49 30 266424242 - **Часы работы:** Сегодня (10 августа) закрыто; 11–12 августа 10:00–18:00; 13 августа 10:00–20:00; 14–16 августа 10:00–18:00 - **Открыто сейчас:** ❌ Нет - **Описание:** Главный музей современного искусства Берлина. Расположен в здании бывшей железнодорожной станции XIX века. Представляет коллекции, специальные выставки и событийные форматы. Входной билет: 16,00 € (льготный 8,00 €), дети до 18 лет бесплатно. ### 3. Berlinische Galerie - **Адрес:** Alte Jakobstraße 124, 10969 Berlin - **Телефон:** +49 30 78902600 - **Часы работы:** Сегодня (10 августа) 10:00–18:00; 11 августа закрыто; 12 августа 10:00–18:00; 13 августа 10:00–20:00; 14–16 августа 10:00–18:00 - **Открыто сейчас:** ✅ Да - **Описание:** Музей современного искусства Берлина с серьёзным международным охватом программ. ### 4. Neue Nationalgalerie - **Адрес:** Potsdamer Straße 50, 10785 Berlin - **Телефон:** +49 30 266424242 - **Часы работы:** Сегодня (10 августа) закрыто; 11–12 августа 10:00–18:00; 13 августа 10:00–20:00; 14–16 августа 10:00–18:00 - **Открыто сейчас:** ❌ Нет - **Описание:** Часть Национальной галереи, специализирующаяся на искусстве XX–XXI веков. ### 5. Gropius Bau - **Адрес:** Niederkirchnerstraße 7, 10963 Berlin - **Телефон:** +49 30 254860 - **Описание:** Выставочная площадка с международным охватом программ современного искусства. ### 6. Sammlung Boros - **Адрес:** Reinhardtstraße 20, 10117 Berlin - **Телефон:** +49 30 27594065 - **Часы работы:** Сегодня (10 августа) закрыто; 13–16 августа 10:00–20:00 - **Описание:** Частная коллекция современного искусства, расположенная в бывшем бункере времён Второй мировой войны. --- **Примечание:** Сегодня (10 августа) открыты KW Institute for Contemporary Art и Berlinische Galerie. Остальные музеи откроются завтра (11 августа). *Источники:,* | E3: PASS | G3: 5 | H3: 4 | I3: 4 | J3: 5 | K3: 5 | L3: 4 | M3: 5 | N3: =IF($E3="","",IF($E3="FAIL","FAIL",ROUND(G3*15%+H3*15%+I3*25%+J3*10%+K3*20%+M3*5%+L3*10%,2))) -> 4.5
A4: 3 | B4: Find the best viewpoints in Lisbon for sunset. | C4: Based on my research, here are the **best viewpoints in Lisbon for watching the sunset**: --- ## 🌅 Top Sunset Viewpoints in Lisbon ### 1. **Miradouro da Senhora do Monte** ⭐ Highest Point - **Location:** Graça hill, northern edge of the old city - **Why it's special:** The highest viewpoint in Lisbon, offering the most complete panorama — terracotta rooftops, São Jorge Castle, and the Tagus River stretching into the distance - **Atmosphere:** Magical golden hour light, but busier than sunrise; arrive early and bring a light layer (the exposed hilltop can be breezy) - **Access:** Free ### 2. **Miradouro de Santa Catarina** - **Why it's special:** Expansive terrace with far-reaching views across the Tagus River - **Atmosphere:** Lively and social — often filled with youthful chatter, street musicians, and clinking glasses from nearby bars - **Best for:** Those who enjoy a vibrant, communal sunset experience ### 3. **Parque Eduardo VII (Northwestern Observation Deck)** - **Why it's special:** A sloped park that feels like you're descending toward the water; position yourself at the northwestern observation deck for a dramatic vista straight down the green lawn toward the Marquês de Pombal monument and the Tagus River - **Best for:** A scenic, open-air setting with sweeping views ### 4. **Ribeira das Naus** - **Location:** Riverside promenade (former shipyard area) - **Why it's special:** Watch the sun set *behind* the iconic 25th of April Bridge from ground level by the water - **Atmosphere:** Relaxed — people relax on wide steps, bike along the path, or sunbathe at the sandy beach area - **Best for:** A riverside sunset with bridge silhouettes ### 5. **MAAT Rooftop** - **Location:** Museum of Art, Architecture and Technology (MAAT), riverside landmark - **Why it's special:** Smooth, curving architecture with direct views of the river and 25th of April Bridge - **Bonus:** Completely free to the public — no museum ticket required - **Best for:** Modern architecture lovers and unobstructed river views ### 6. **Miradouro da Graça (Sophia de Mello Breyner Andresen)** - **Location:** Rua dos Lagares, 1100 Lisboa - **Why it's special:** Lower than Senhora do Monte but more social, with a café and kiosk on-site - **Atmosphere:** Relaxed and accessible, great for lingering with a drink - **Access:** Open 24 hours ### 7. **Castelo de São Jorge Viewpoint** - **Why it's special:** Lisbon's most iconic miradouro, built at the end of the 18th century with supporting walls dating back to the 14th century. Offers a monumental panoramic view dominating the entire landscape, with cannons pointing toward the river - **Atmosphere:** Historic and dramatic, with shade from indigenous trees - **Note:** Requires a climb up to the castle --- ## 💡 Tips for Sunset Viewing - **Arrive early** — popular spots fill up quickly during golden hour - **Bring a light layer** — especially for elevated viewpoints like Senhora do Monte, which can be cooler and windier - **Sunset timing in August:** Around 20:30–21:00 local time in Lisbon - **Free options:** Most miradouros are free; MAAT rooftop is also free Would you like help planning a route between any of these viewpoints or getting directions to a specific one? | D4: Tool result (places_search): {"places":[{"ref":"plc_78018ac931","id":"9q_IQFmptX82bByHEJwVgQ","name":"Telecabine Lisboa","address":"Passeio das Tágides, 1990 Lisboa","categories":["scenic/panoramic view"],"phones":["+351 21 895 6143"],"rating":null,"review_count":null,"hours_text":"Next 7 days: Aug 10–16 11:00–18:00","open_24h":false,"is_open_now":false,"accessibility":[],"distance_m":null},{"ref":"plc_b2169efd51","id":"6yxYqEmR5XDUevE_sAKbFg","name":"Jacarandás do Restelo","address":"Avenida do Restelo, 1400 Lisboa","categories":["scenic/panoramic view"],"phones":[],"rating":null,"review_count":null,"hours_text":"Open 24 hours for the next 7 days","open_24h":true,"is_open_now":true,"accessibility":[],"distance_m":null},{"ref":"plc_16566ae328","id":"HwYybqVO7fol8QVF7J57uw","name":"Miradouro dos Barros","address":"Rua Damasceno Monteiro, 1170 Lisboa","categories":["scenic/panoramic view"],"phones":[],"rating":null,"review_count":null,"hours_text":"Open 24 hours for the next 7 days","open_24h":true,"is_open_now":true,"accessibility":[],"distance_m":null},{"ref":"plc_0a631f6f2b","id":"EI1tXdWFYEaooNb7cQSNRA","name":"Miradouro do Chão do Loureiro","address":"Calçada do Marquês de Tancos, 1100 Lisboa","categories":["scenic/panoramic view"],"phones":[],"rating":null,"review_count":null,"hours_text":null,"open_24h":null,"is_open_now":null,"accessibility":[],"distance_m":null},{"ref":"plc_b6abf394a1","id":"P89rdmELWnB7-FePmHNiow","name":"Zona de Spotters","address":"Avenida Santos e Castro, 1750 Lisboa","categories":["scenic/panoramic view"],"phones":[],"rating":null,"review_count":null,"hours_text":"Open 24 hours for the next 7 days","open_24h":true,"is_open_now":true,"accessibility":[],"distance_m":null},{"ref":"plc_55541d3af3","id":"TBBTY_4hXEsjmhUo1QsMSg","name":"Miradouro do Jardim do Torel","address":"Travessa da Cruz do Torel, 1150 Lisboa","categories":["scenic/panoramic view"],"phones":[],"rating":null,"review_count":null,"hours_text":"Next 7 days: Aug 10–16 08:00–20:00","open_24h":false,"is_open_now":true,"accessibility":[],"distance_m":null},{"ref":"plc_ce4c3f0535","id":"pJ0bcpEYkdwZTIO4dXHcCw","name":"Miradouro do Bairro do Alvito","address":"Estrada do Clube de Ténis, 1300 Lisboa","categories":["scenic/panoramic view"],"phones":[],"rating":null,"review_count":null,"hours_text":"Open 24 hours for the next 7 days","open_24h":true,"is_open_now":true,"accessibility":[],"distance_m":null},{"ref":"plc_7ad6ea9d4b","id":"AbitAsQ4q4uAmW8R1qY94w","name":"Miradouro do Arboreto","address":"Estacada do Arboreto, 1990 Lisboa","categories":["scenic/panoramic view"],"phones":[],"rating":null,"review_count":null,"hours_text":"Open 24 hours for the next 7 days","open_24h":true,"is_open_now":true,"accessibility":[],"distance_m":null},{"ref":"plc_1d6fe4d932","id":"-QqUy3HvBNzhmxiGNoFqUg","name":"Miradouro dos Moinhos de Santana","address":"Rua Tristão Vaz, 1400 Lisboa","categories":["scenic/panoramic view"],"phones":["+351 915 225 592"],"rating":null,"review_count":null,"hours_text":"Next 7 days: Aug 10–16 09:00–18:00","open_24h":false,"is_open_now":false,"accessibility":[],"distance_m":null},{"ref":"plc_44f1f0a8c5","id":"8Sy3KR3XJXubdLjXXZ9Gzw","name":"Miradouro da Graça (Sophia de Mello Breyner Andresen)","address":"Rua dos Lagares, 1100 Lisboa","categories":["scenic/panoramic view"],"phones":["+351 21 031 2899"],"rating":null,"review_count":null,"hours_text":"Open 24 hours for the next 7 days","open_24h":true,"is_open_now":true,"accessibility":[],"distance_m":null}],"area":{"ref":"plc_904cc2fb84","name":"Lisboa","address":"Lisboa, Portugal Continental, Portugal"},"truncated":true,"anchor":null,"resolved":[],"returned_count":10,"warnings":["2GIS does not cover the requested locality; using TomTom.","TomTom supplied neither opening hours nor a phone number for 1 results; their current operation could not be verified from this response."]} Tool result (web_search): {"query":"best viewpoints in Lisbon for sunset 2026","results":[{"ref":"src_85e6939ec0","title":"8 sunset spots in Lisbon for the best golden hour views","domain":"www.getyourguide.com","snippet":"Since Lisbon is a city of hills, there are numerous elevated viewpoints like Miradouro da Senhora do Monte that make for top-tier sunset spots. Prefer a sunset from down by the water? Riverfront destinations like the Ribeira das Naus promenade are where to go. Covering locations above the city as well as those down on the water, this guide on where to watch the sunset in Lisbon points you in the right direction.\n...\nIf you think the higher the better with sunset viewing, then you have to visit Miradouro da Senhora do Monte — the highest point in the city. At this popular lookout point at the Chapel of Our Lady of the Mountain, you’ll see a sea of terracotta rooftops all the way to São Jorge Castle and the Tagus River as the sun goes down.\n...\nOften buzzing with youthful chatter, music from street performers, and the sound of clinking beer glasses, the expansive terrace at the Miradouro de Santa Catarina makes for one of the best places to watch the sunset in Lisbon with its far-reaching views across the Tagus River.\n...\nWith its sloped design, the well-manicured Parque Eduardo VII seems like it’s delivering you right to the water. For a spectacular sunset view, position yourself at the observation deck at the park’s northwestern section to look straight down the green lawn to the Marquês de Pombal monument and the Tagus River.\n...\nOnce a shipyard, Ribeira das Naus is a riverfront promenade where you’ll find people relaxing on the wide steps, biking up and down the path, and sunbathing at the sandy beach area. Sunset is a special time here since you can watch the sun go down behind the 25th of April Bridge in the distance.\n...\nof Art, Architecture, and Technology (MAAT) is an eye-catching riverside landmark with its smooth, curving design, and one of its coolest features is a rooftop accessible to pedestrians. Better still, it’s free to the public — no museum ticket necessary. With its direct views of the river and 25th of April Bridge, it’s one of","published_date":"2026-07-13"},{"_omitted_items":8},{"ref":"src_b02c9d8d2b","title":"Miradouro de São Jorge | Visit Lisboa","domain":"www.visitlisboa.com","snippet":"## Miradouro de São Jorge\n...\nLet the most iconic miradouro in Lisbon cast its spell over you. Earn the right to the best view in the city after tackling the steep climb up to the castle.\n...\nLisbon’s most iconic viewing point, or miradouro, is inside the Castelo de São Jorge and has a monumental panoramic view of the city and river, dominating the whole surrounding landscape. It was built at the end of the 18th century, but its supporting walls date from the 14th. Much of it was totally rebuilt in 1940 in a massive preservation exercise. The miradouro is inside the castle and is an ideal place to rest after wandering up the streets to reach it. Its cannons point towards the river in an eternal challenge to whoever dares to invade this proud city. With endless shade offered by magnificent examples of indigenous trees, this is an obligatory place to stop and contemplate Lisbon.","published_date":null}]} Tool result (web_search): {"query":"Miradouro da Senhora do Monte sunset Lisbon best view 2026","results":[{"ref":"src_6dec0faa5c","title":"Miradouro da Senhora do Monte: Best Time + Route · Love Lisbon","domain":"lovelisbon.com","snippet":"- One of Lisbon’s biggest panoramas — rooftops, river, and the whole city layout.\n- Best at sunrise for calm; magical at sunset for warm light (but busier).\n- Plan it as ‘up first, down later’ so the hill feels satisfying, not exhausting.\n- Pair it with Graça’s streets and Alfama’s lanes for a perfect old-Lisbon day.\n- Bring a light layer — the hill can catch a cooler breeze.\n- Choose one viewpoint per day and linger (this one is a great pick).\n...\nIf you want Senhora do Monte to feel peaceful, sunrise is the move. You’ll get softer light, quieter streets, and that rare feeling of having Lisbon to yourself.\n...\nIf you want romance, sunset is beautiful — just expect more people. The trick is to arrive early, bring a light layer, and treat it as the evening anchor rather than one stop in a rushed list.\n...\n- Calmest: sunrise (or early morning).\n- Most cinematic: golden hour into sunset (busier, but gorgeous).\n- Best habit: show up early and stay a little after the sun drops.\n...\nMiradouro da Senhora do Monte sits at the top of the Graça hill, on the northern edge of the old city — it’s one of the highest of Lisbon’s named viewpoints, which is exactly why the panorama is so complete. From the terrace, beside a small chapel, you look back across the entire historic city: the castle on its hill in the foreground, the rooftops of Mouraria and Baixa below, and the Tagus stretching wide behind it all.\n...\n. The nearby Miradouro da Graça is lower and more social, with a café and a kiosk\n...\nBecause it’s exposed at the top of the hill, it can be breezy and cooler than the streets below; bring a light layer, especially for sunrise or after sunset. The classic mistake is treating it as a quick tram stop — the reward is in lingering, so build it into a slower plan rather than a dash. And as with anywhere a crowd gathers at sunset, keep an eye on your belongings. Treat any kiosk or vendor specifics as worth confirming on the day, since they change.","published_date":"2026-02-10"},{"_omitted_items":3},{"ref":"src_3f72d17222","title":"Miradouro da Senhora do Monte - Like A Local Guide","domain":"likealocalguide.com","snippet":"Miradouro da Senhora do Monte - Like A Local Guide\n\n# Miradouro da Senhora do Monte\n\nGraça • ★ 4.7 • $\n\nThe highest of Lisbon’s viewpoints, offering castle, rooftops and river in one sweep at sunset. Up in Graca, this free-to-enjoy lookout is a local favourite for golden hour. Bring a drink and settle in as the light softens over the city.","published_date":"2026-07-03"}]} Final answer: Based on my research, here are the **best viewpoints in Lisbon for watching the sunset**: --- ## 🌅 Top Sunset Viewpoints in Lisbon ### 1. **Miradouro da Senhora do Monte** ⭐ Highest Point - **Location:** Graça hill, northern edge of the old city - **Why it's special:** The highest viewpoint in Lisbon, offering the most complete panorama — terracotta rooftops, São Jorge Castle, and the Tagus River stretching into the distance - **Atmosphere:** Magical golden hour light, but busier than sunrise; arrive early and bring a light layer (the exposed hilltop can be breezy) - **Access:** Free ### 2. **Miradouro de Santa Catarina** - **Why it's special:** Expansive terrace with far-reaching views across the Tagus River - **Atmosphere:** Lively and social — often filled with youthful chatter, street musicians, and clinking glasses from nearby bars - **Best for:** Those who enjoy a vibrant, communal sunset experience ### 3. **Parque Eduardo VII (Northwestern Observation Deck)** - **Why it's special:** A sloped park that feels like you're descending toward the water; position yourself at the northwestern observation deck for a dramatic vista straight down the green lawn toward the Marquês de Pombal monument and the Tagus River - **Best for:** A scenic, open-air setting with sweeping views ### 4. **Ribeira das Naus** - **Location:** Riverside promenade (former shipyard area) - **Why it's special:** Watch the sun set *behind* the iconic 25th of April Bridge from ground level by the water - **Atmosphere:** Relaxed — people relax on wide steps, bike along the path, or sunbathe at the sandy beach area - **Best for:** A riverside sunset with bridge silhouettes ### 5. **MAAT Rooftop** - **Location:** Museum of Art, Architecture and Technology (MAAT), riverside landmark - **Why it's special:** Smooth, curving architecture with direct views of the river and 25th of April Bridge - **Bonus:** Completely free to the public — no museum ticket required - **Best for:** Modern architecture lovers and unobstructed river views ### 6. **Miradouro da Graça (Sophia de Mello Breyner Andresen)** - **Location:** Rua dos Lagares, 1100 Lisboa - **Why it's special:** Lower than Senhora do Monte but more social, with a café and kiosk on-site - **Atmosphere:** Relaxed and accessible, great for lingering with a drink - **Access:** Open 24 hours ### 7. **Castelo de São Jorge Viewpoint** - **Why it's special:** Lisbon's most iconic miradouro, built at the end of the 18th century with supporting walls dating back to the 14th century. Offers a monumental panoramic view dominating the entire landscape, with cannons pointing toward the river - **Atmosphere:** Historic and dramatic, with shade from indigenous trees - **Note:** Requires a climb up to the castle --- ## 💡 Tips for Sunset Viewing - **Arrive early** — popular spots fill up quickly during golden hour - **Bring a light layer** — especially for elevated viewpoints like Senhora do Monte, which can be cooler and windier - **Sunset timing in August:** Around 20:30–21:00 local time in Lisbon - **Free options:** Most miradouros are free; MAAT rooftop is also free Would you like help planning a route between any of these viewpoints or getting directions to a specific one? | E4: PASS | G4: 5 | H4: 4 | I4: 3 | J4: 5 | K4: 5 | L4: 4 | M4: 5 | N4: =IF($E4="","",IF($E4="FAIL","FAIL",ROUND(G4*15%+H4*15%+I4*25%+J4*10%+K4*20%+M4*5%+L4*10%,2))) -> 4.25
A5: 4 | B5: Suggest traditional trattorias in Trastevere. | C5: Based on my search, here are two well-known traditional trattorias in Trastevere, Rome: --- ### 🍝 **Checco Er Carettiere** - **Address:** Via Benedetta 10, 00153 Roma - **Phone:** +39 06 580 0985 - **History:** A historic family-run trattoria that opened in 1935, making it one of the oldest restaurants in the neighborhood. The establishment has been passed down through generations of the Checco family. - **Hours (Aug 10–16):** 12:00–15:00, 19:00–24:00 - **Currently open:** ✅ Yes --- ### 🍝 **Trattoria da Lucia** - **Address:** Vicolo del Mattonato 2, 00153 Roma - **Phone:** +39 06 580 3601 - **History:** A beloved traditional trattoria operating since 1938, located in a charming alley (vicolo) in the heart of Trastevere. It is recommended by numerous international Rome guides. - **Hours:** - Aug 10–11: Closed - Aug 12: 19:30–23:00 - Aug 13–16: 12:30–15:00, 19:30–23:00 - **Currently open:** ❌ No (closed today) --- Both trattorias are deeply rooted in Trastevere's culinary tradition, offering authentic Roman cuisine in historic settings. If you're planning a visit today, **Checco Er Carettiere** is currently open. *Sources:,* | D5: Tool result (places_search): {"places":[],"area":{"ref":"plc_23ea44258d","name":"Roma","address":"Roma, Lazio, Italia"},"truncated":false,"anchor":null,"resolved":[],"returned_count":0,"warnings":["2GIS does not cover the requested locality; using TomTom."]} Tool result (web_search): {"query":"traditional trattorias in Trastevere Rome","results":[{"ref":"src_9878e9adb3","title":"History of Checco er Carettiere | Trastevere Restaurant","domain":"www.checcoercarettiere.it","snippet":"generations of Checco Er Carettiere restaurant in Trastevere.\n...\nThe story of Checco Er Carettiere began back in the 1930s. In fact, Checco’s Tavern opened in 1935, when Francesco and his wife Diomi…","published_date":"2020-02-10"},{"_omitted_items":3},{"ref":"src_526f4f7522","title":"Roma, Trattoria da Lucia a Trastevere dal 1938 - Luciano Pignataro Wine Blog","domain":"www.lucianopignataro.it","snippet":"Diciamo subito che da Lucia a Trastevere, al vicolo del Mattonato, non siete di sicuro nella versione junk food quanto piuttosto in un localino consigliato da tante guide di Roma di tutto il mondo, R…","published_date":"2019-10-26"}]} Tool result (places_search): {"places":[],"area":null,"truncated":false,"anchor":null,"resolved":[{"client_id":"checco","input_name":"Checco Er Carettiere","status":"resolved","place":{"ref":"plc_42e1ddd191","id":"zW69GBRG1f_D3ePURDOwjA","name":"Checco Er Carettiere","address":"Via Benedetta 10, 00153 Roma","categories":["restaurant","italian"],"phones":["+39 06 580 0985"],"rating":null,"review_count":null,"hours_text":"Next 7 days: Aug 10–16 12:00–15:00, 19:00–24:00","open_24h":false,"is_open_now":true,"accessibility":[],"distance_m":null},"options":[],"error":null},{"client_id":"lucia","input_name":"Trattoria da Lucia","status":"resolved","place":{"ref":"plc_07dba703a0","id":"jRYouEGWKw54tdIRCEQFGw","name":"Trattoria Da Lucia","address":"Vicolo del Mattonato 2, 00153 Roma","categories":["restaurant","italian"],"phones":["+39 06 580 3601"],"rating":null,"review_count":null,"hours_text":"Next 7 days: Aug 10–11 closed; Aug 12 19:30–23:00; Aug 13–16 12:30–15:00, 19:30–23:00","open_24h":false,"is_open_now":false,"accessibility":[],"distance_m":null},"options":[],"error":null}],"returned_count":2,"warnings":["2GIS does not cover the requested locality; using TomTom."]} Final answer: Based on my search, here are two well-known traditional trattorias in Trastevere, Rome: --- ### 🍝 **Checco Er Carettiere** - **Address:** Via Benedetta 10, 00153 Roma - **Phone:** +39 06 580 0985 - **History:** A historic family-run trattoria that opened in 1935, making it one of the oldest restaurants in the neighborhood. The establishment has been passed down through generations of the Checco family. - **Hours (Aug 10–16):** 12:00–15:00, 19:00–24:00 - **Currently open:** ✅ Yes --- ### 🍝 **Trattoria da Lucia** - **Address:** Vicolo del Mattonato 2, 00153 Roma - **Phone:** +39 06 580 3601 - **History:** A beloved traditional trattoria operating since 1938, located in a charming alley (vicolo) in the heart of Trastevere. It is recommended by numerous international Rome guides. - **Hours:** - Aug 10–11: Closed - Aug 12: 19:30–23:00 - Aug 13–16: 12:30–15:00, 19:30–23:00 - **Currently open:** ❌ No (closed today) --- Both trattorias are deeply rooted in Trastevere's culinary tradition, offering authentic Roman cuisine in historic settings. If you're planning a visit today, **Checco Er Carettiere** is currently open. *Sources:,* | E5: PASS | G5: 5 | H5: 4 | I5: 4 | J5: 4 | K5: 5 | L5: 5 | M5: 5 | N5: =IF($E5="","",IF($E5="FAIL","FAIL",ROUND(G5*15%+H5*15%+I5*25%+J5*10%+K5*20%+M5*5%+L5*10%,2))) -> 4.5
